Workbook

Sheet Precipitacion
A2: VARIABLE | B2: PRECIPITACION (mm) | C2: MES | D2: =VLOOKUP(E2,Maximos!AS1:AU13,2,FALSE) -> JUNIO | E2: 6 | F2: AÑO | G2: 2026 | H2: DIAS | I2: =VLOOKUP(E2,Maximos!AS1:AU13,3,FALSE) -> 30 | J2: Máximo | K2: =MAX(K5:K798) -> 114 | L2: =MAX(L5:L798) -> 150 | M2: =MAX(M5:M798) -> 136 | N2: =MAX(N5:N798) -> 153 | O2: =MAX(O5:O798) -> 119 | P2: =MAX(P5:P798) -> 134.6 | Q2: =MAX(Q5:Q798) -> 145 | R2: =MAX(R5:R798) -> 136 | ... AO2: =MAX(AO5:AO798) -> 0 | AP2: =MAX(K2:AO2) -> 157
A4: CODIGO | B4: ESTACION | C4: AREA_OP | D4: LON | E4: LAT | F4: ELEV | G4: COD_DPTO | H4: COD_MUNICIPIO | I4: DEPARTAMENTO | J4: MUNICIPIO | K4: 1 | L4: 2 | M4: 3 | N4: 4 | O4: 5 | P4: 6 | Q4: 7 | R4: 8 | S4: 9 | T4: 10 | U4: 11 | V4: 12 | W4: 13 | X4: 14 | Y4: 15 | Z4: 16 | AA4: 17 | AB4: 18 | AC4: 19 | AD4: 20 | AE4: 21 | AF4: 22 | AG4: 23 | AH4: 24 | AI4: 25 | AJ4: 26 | AK4: 27 | AL4: 28 | AM4: 29 | AN4: 30 | AO4: 31 | AP4: NUM_DATOS | AQ4: PREC_MENSUAL | AR4: MEDIA_MULTIANUAL | AS4: ANOMALIA_R | AT4: ANOMALIA_P | AU4: MAX_MES | AV4: MAX_HISTORICO | AW4: FECHA | AX4: DIFERENCIA
A5: 17015010 | B5: Aeropuerto Sesquicentenario | C5: Met_Aeronautica | D5: -81.703889 | E5: 12.586944 | F5: 1 | G5: 88 | H5: 88001 | I5: Archipiélago de San Andres, Providencia y Santa Catalina | J5: San Andrés | K5: 0.2 | L5: 1.4 | M5: 0.9 | N5: 0.2 | O5: 1.3 | P5: 26.6 | Q5: 1.2 | R5: 57.8 | S5: 3.4 | T5: 2.4 | U5: 0 | V5: 2.4 | W5: 0 | X5: 0.1 | Y5: 0 | Z5: 0.8 | AA5: 0 | AB5: 2.3 | AC5: 0.2 | AD5: 10.8 | AE5: 0.2 | AF5: 4.3 | AG5: 1.1 | AH5: 1.8 | AI5: 1.6 | AJ5: 0 | AK5: 0 | AL5: 0.6 | AM5: 0 | AN5: 3 | AP5: =COUNTIF(K5:AO5,">=0") -> 30 | AQ5: =IF(AP5>0,SUM(K5:AO5),"") -> 124.6 | AR5: =IFERROR(VLOOKUP(A5,Climatologia_PP!A:U,9+Precipitacion!$E$2,FALSE),"") -> 196.025 | AS5: =IFERROR((AQ5/AR5)*100,"") -> 63.563321 | AT5: =IFERROR(IF(AND((AQ5*$I$2*100/(AR5*AP5))>100+3.33*AQ5-AR5*AP5/$I$2,AR5<30),IF(100+3.33*AQ5-AR5*AP5/$I$2>200,200,100+3.33*AQ5-AR5*AP5/$I$2),IF((AQ5*$I$2*100/(AR5*AP5))<100+AQ5-3.33*AR5*AP5/$I$2,100+AQ5-3.33*AR5*AP5/$I$2,IF((AQ5*$I$2*100/(AR5*AP5))>200,200,(AQ5*$I$2*100/(AR5*AP5))))),"") -> 63.563321 | AU5: =IF(AP5>0,MAX(K5:AO5),"") -> 57.8 | AV5: =IFERROR(VLOOKUP(A5,Maximos!A:AQ,8+(Precipitacion!$E$2-1)*3,FALSE),"") -> 192.7 | AW5: {=IFERROR( _xlfn.LET( _xlpm.mesNum, E$2, _xlpm.mesTxt, INDEX({"ENERO","FEBRERO","MARZO","ABRIL","MAYO","JUNIO","JULIO","AGOSTO","SEPTIEMBRE","OCTUBRE","NOVIEMBRE","DICIEMBRE"}, _xlpm.mesNum), _xlpm.colIni, MATCH(_xlpm.mesTxt, Maximos!$1:$1, 0), _xlpm.fila, MATCH($A5, Maximos!$A:$A, 0), _xlpm.anio, INDEX(Maximos!$A:$ZZ, _xlpm.fila, _xlpm.colIni+1), _xlpm.dia, INDEX(Maximos!$A:$ZZ, _xlpm.fila, _xlpm.colIni+2), IF(OR(_xlpm.anio="",_xlpm.dia=""), "No aplica", DATE(_xlpm.anio, _xlpm.mesNum, _xlpm.dia)) ), "")} -> 45816 | AX5: =IFERROR(AU5-AV5,"NA") -> -134.9
A6: 17025020 | B6: Aeropuerto El Embrujo | C6: Met_Aeronautica | D6: -81.357722 | E6: 13.3595 | F6: 7 | G6: 88 | H6: 88564 | I6: Archipiélago de San Andres, Providencia y Santa Catalina | J6: Providencia | K6: 0 | L6: 0 | M6: 0 | N6: 0 | O6: 0 | P6: 0 | Q6: 0 | R6: 11.2 | S6: 0 | T6: 0 | U6: 0 | V6: 0 | W6: 0 | X6: 0 | Y6: 2.8 | Z6: 1.4 | AA6: 0 | AB6: 0 | AC6: 1.2 | AD6: 0.7 | AE6: 0 | AF6: 0 | AG6: 0 | AH6: 0 | AI6: 0 | AJ6: 1.5 | AK6: 0 | AL6: 0 | AM6: 0 | AN6: 0 | AP6: =COUNTIF(K6:AO6,">=0") -> 30 | AQ6: =IF(AP6>0,SUM(K6:AO6),"") -> 18.8 | AR6: =IFERROR(VLOOKUP(A6,Climatologia_PP!A:U,9+Precipitacion!$E$2,FALSE),"") -> 154.54444 | AS6: =IFERROR((AQ6/AR6)*100,"") -> 12.164785 | AT6: =IFERROR(IF(AND((AQ6*$I$2*100/(AR6*AP6))>100+3.33*AQ6-AR6*AP6/$I$2,AR6<30),IF(100+3.33*AQ6-AR6*AP6/$I$2>200,200,100+3.33*AQ6-AR6*AP6/$I$2),IF((AQ6*$I$2*100/(AR6*AP6))<100+AQ6-3.33*AR6*AP6/$I$2,100+AQ6-3.33*AR6*AP6/$I$2,IF((AQ6*$I$2*100/(AR6*AP6))>200,200,(AQ6*$I$2*100/(AR6*AP6))))),"") -> 12.164785 | AU6: =IF(AP6>0,MAX(K6:AO6),"") -> 11.2 | AV6: =IFERROR(VLOOKUP(A6,Maximos!A:AQ,8+(Precipitacion!$E$2-1)*3,FALSE),"") -> 188.7 | AW6: {=IFERROR( _xlfn.LET( _xlpm.mesNum, E$2, _xlpm.mesTxt, INDEX({"ENERO","FEBRERO","MARZO","ABRIL","MAYO","JUNIO","JULIO","AGOSTO","SEPTIEMBRE","OCTUBRE","NOVIEMBRE","DICIEMBRE"}, _xlpm.mesNum), _xlpm.colIni, MATCH(_xlpm.mesTxt, Maximos!$1:$1, 0), _xlpm.fila, MATCH($A6, Maximos!$A:$A, 0), _xlpm.anio, INDEX(Maximos!$A:$ZZ, _xlpm.fila, _xlpm.colIni+1), _xlpm.dia, INDEX(Maximos!$A:$ZZ, _xlpm.fila, _xlpm.colIni+2), IF(OR(_xlpm.anio="",_xlpm.dia=""), "No aplica", DATE(_xlpm.anio, _xlpm.mesNum, _xlpm.dia)) ), "")} -> 39971 | AX6: =IFERROR(AU6-AV6,"NA") -> -177.5
A7: 15015050 | B7: Aeropuerto Simón Bolívar | C7: Met_Aeronautica | D7: -74.228889 | E7: 11.128333 | F7: 4 | G7: 47 | H7: 47001 | I7: Magdalena | J7: Santa Marta | K7: 0 | L7: 2.3 | M7: 0.1 | N7: 0.9 | O7: 32.8 | P7: 1.5 | Q7: 0 | R7: 0 | S7: 2 | T7: 0 | U7: 0 | V7: 0 | W7: 0 | X7: 0 | Y7: 1.8 | Z7: 0 | AA7: 6.6 | AB7: 0 | AC7: 0 | AD7: 0 | AE7: 0 | AF7: 0 | AG7: 0 | AH7: 0 | AI7: 0 | AJ7: 0 | AK7: 0 | AL7: 0 | AM7: 0 | AN7: 0 | AP7: =COUNTIF(K7:AO7,">=0") -> 30 | AQ7: =IF(AP7>0,SUM(K7:AO7),"") -> 48 | AR7: =IFERROR(VLOOKUP(A7,Climatologia_PP!A:U,9+Precipitacion!$E$2,FALSE),"") -> 60.189286 | AS7: =IFERROR((AQ7/AR7)*100,"") -> 79.748413 | AT7: =IFERROR(IF(AND((AQ7*$I$2*100/(AR7*AP7))>100+3.33*AQ7-AR7*AP7/$I$2,AR7<30),IF(100+3.33*AQ7-AR7*AP7/$I$2>200,200,100+3.33*AQ7-AR7*AP7/$I$2),IF((AQ7*$I$2*100/(AR7*AP7))<100+AQ7-3.33*AR7*AP7/$I$2,100+AQ7-3.33*AR7*AP7/$I$2,IF((AQ7*$I$2*100/(AR7*AP7))>200,200,(AQ7*$I$2*100/(AR7*AP7))))),"") -> 79.748413 | AU7: =IF(AP7>0,MAX(K7:AO7),"") -> 32.8 | AV7: =IFERROR(VLOOKUP(A7,Maximos!A:AQ,8+(Precipitacion!$E$2-1)*3,FALSE),"") -> 105 | AW7: {=IFERROR( _xlfn.LET( _xlpm.mesNum, E$2, _xlpm.mesTxt, INDEX({"ENERO","FEBRERO","MARZO","ABRIL","MAYO","JUNIO","JULIO","AGOSTO","SEPTIEMBRE","OCTUBRE","NOVIEMBRE","DICIEMBRE"}, _xlpm.mesNum), _xlpm.colIni, MATCH(_xlpm.mesTxt, Maximos!$1:$1, 0), _xlpm.fila, MATCH($A7, Maximos!$A:$A, 0), _xlpm.anio, INDEX(Maximos!$A:$ZZ, _xlpm.fila, _xlpm.colIni+1), _xlpm.dia, INDEX(Maximos!$A:$ZZ, _xlpm.fila, _xlpm.colIni+2), IF(OR(_xlpm.anio="",_xlpm.dia=""), "No aplica", DATE(_xlpm.anio, _xlpm.mesNum, _xlpm.dia)) ), "")} -> 35973 | AX7: =IFERROR(AU7-AV7,"NA") -> -72.2
A8: 14015080 | B8: Aeropuerto Rafael Nuñez | C8: Met_Aeronautica | D8: -75.516028 | E8: 10.44725 | F8: 2 | G8: 13 | H8: 13001 | I8: Bolívar | J8: Cartagena De Indias | K8: 0.2 | L8: 4 | M8: 0 | N8: 0 | O8: 0 | P8: 26 | Q8: 0 | R8: 1.8 | S8: 0 | T8: 0 | U8: 0 | V8: 0 | W8: 0 | X8: 1.4 | Y8: 30.3 | Z8: 0 | AA8: 0.9 | AB8: 0 | AC8: 0 | AD8: 8 | AE8: 0 | AF8: 0 | AG8: 0 | AH8: 0 | AI8: 0 | AJ8: 0 | AK8: 0 | AL8: 0 | AM8: 0 | AN8: 0 | AP8: =COUNTIF(K8:AO8,">=0") -> 30 | AQ8: =IF(AP8>0,SUM(K8:AO8),"") -> 72.6 | AR8: =IFERROR(VLOOKUP(A8,Climatologia_PP!A:U,9+Precipitacion!$E$2,FALSE),"") -> 92.517241 | AS8: =IFERROR((AQ8/AR8)*100,"") -> 78.47186 | AT8: =IFERROR(IF(AND((AQ8*$I$2*100/(AR8*AP8))>100+3.33*AQ8-AR8*AP8/$I$2,AR8<30),IF(100+3.33*AQ8-AR8*AP8/$I$2>200,200,100+3.33*AQ8-AR8*AP8/$I$2),IF((AQ8*$I$2*100/(AR8*AP8))<100+AQ8-3.33*AR8*AP8/$I$2,100+AQ8-3.33*AR8*AP8/$I$2,IF((AQ8*$I$2*100/(AR8*AP8))>200,200,(AQ8*$I$2*100/(AR8*AP8))))),"") -> 78.47186 | AU8: =IF(AP8>0,MAX(K8:AO8),"") -> 30.3 | AV8: =IFERROR(VLOOKUP(A8,Maximos!A:AQ,8+(Precipitacion!$E$2-1)*3,FALSE),"") -> 129.3 | AW8: {=IFERROR( _xlfn.LET( _xlpm.mesNum, E$2, _xlpm.mesTxt, INDEX({"ENERO","FEBRERO","MARZO","ABRIL","MAYO","JUNIO","JULIO","AGOSTO","SEPTIEMBRE","OCTUBRE","NOVIEMBRE","DICIEMBRE"}, _xlpm.mesNum), _xlpm.colIni, MATCH(_xlpm.mesTxt, Maximos!$1:$1, 0), _xlpm.fila, MATCH($A8, Maximos!$A:$A, 0), _xlpm.anio, INDEX(Maximos!$A:$ZZ, _xlpm.fila, _xlpm.colIni+1), _xlpm.dia, INDEX(Maximos!$A:$ZZ, _xlpm.fila, _xlpm.colIni+2), IF(OR(_xlpm.anio="",_xlpm.dia=""), "No aplica", DATE(_xlpm.anio, _xlpm.mesNum, _xlpm.dia)) ), "")} -> 44739 | AX8: =IFERROR(AU8-AV8,"NA") -> -99
A9: 29045190 | B9: Aeropuerto Ernesto Cortissoz - AUT | C9: Met_Aeronautica | D9: -74.779722 | E9: 10.917778 | F9: 14 | G9: 8 | H9: 8758 | I9: Atlántico | J9: Soledad | AP9: =COUNTIF(K9:AO9,">=0") -> 0 | AQ9: =IF(AP9>0,SUM(K9:AO9),"") | AR9: =IFERROR(VLOOKUP(A9,Climatologia_PP!A:U,9+Precipitacion!$E$2,FALSE),"") -> 87.478571 | AS9: =IFERROR((AQ9/AR9)*100,"") | AT9: =IFERROR(IF(AND((AQ9*$I$2*100/(AR9*AP9))>100+3.33*AQ9-AR9*AP9/$I$2,AR9<30),IF(100+3.33*AQ9-AR9*AP9/$I$2>200,200,100+3.33*AQ9-AR9*AP9/$I$2),IF((AQ9*$I$2*100/(AR9*AP9))<100+AQ9-3.33*AR9*AP9/$I$2,100+AQ9-3.33*AR9*AP9/$I$2,IF((AQ9*$I$2*100/(AR9*AP9))>200,200,(AQ9*$I$2*100/(AR9*AP9))))),"") | AU9: =IF(AP9>0,MAX(K9:AO9),"") | AV9: =IFERROR(VLOOKUP(A9,Maximos!A:AQ,8+(Precipitacion!$E$2-1)*3,FALSE),"") -> 104.1 | AW9: {=IFERROR( _xlfn.LET( _xlpm.mesNum, E$2, _xlpm.mesTxt, INDEX({"ENERO","FEBRERO","MARZO","ABRIL","MAYO","JUNIO","JULIO","AGOSTO","SEPTIEMBRE","OCTUBRE","NOVIEMBRE","DICIEMBRE"}, _xlpm.mesNum), _xlpm.colIni, MATCH(_xlpm.mesTxt, Maximos!$1:$1, 0), _xlpm.fila, MATCH($A9, Maximos!$A:$A, 0), _xlpm.anio, INDEX(Maximos!$A:$ZZ, _xlpm.fila, _xlpm.colIni+1), _xlpm.dia, INDEX(Maximos!$A:$ZZ, _xlpm.fila, _xlpm.colIni+2), IF(OR(_xlpm.anio="",_xlpm.dia=""), "No aplica", DATE(_xlpm.anio, _xlpm.mesNum, _xlpm.dia)) ), "")} -> 17686 | AX9: =IFERROR(AU9-AV9,"NA") -> NA
A10: 15065180 | B10: Aeropuerto Almirante Padilla | C10: Met_Aeronautica | D10: -72.917667 | E10: 11.529611 | F10: 4 | G10: 44 | H10: 44001 | I10: La Guajira | J10: Riohacha | K10: 0 | L10: 0 | M10: 2 | N10: 8 | O10: 0 | P10: 84 | Q10: 0.7 | R10: 0 | S10: 0.7 | T10: 0 | U10: 0 | V10: 0 | W10: 0 | X10: 0 | Y10: 0 | Z10: 0 | AA10: 0 | AB10: 0 | AC10: 0 | AD10: 0 | AE10: 0 | AF10: 0 | AG10: 0 | AH10: 0 | AI10: 0 | AJ10: 0 | AK10: 0 | AL10: 0 | AM10: 0 | AN10: 0 | AP10: =COUNTIF(K10:AO10,">=0") -> 30 | AQ10: =IF(AP10>0,SUM(K10:AO10),"") -> 95.4 | AR10: =IFERROR(VLOOKUP(A10,Climatologia_PP!A:U,9+Precipitacion!$E$2,FALSE),"") -> 50.707692 | AS10: =IFERROR((AQ10/AR10)*100,"") -> 188.13714 | AT10: =IFERROR(IF(AND((AQ10*$I$2*100/(AR10*AP10))>100+3.33*AQ10-AR10*AP10/$I$2,AR10<30),IF(100+3.33*AQ10-AR10*AP10/$I$2>200,200,100+3.33*AQ10-AR10*AP10/$I$2),IF((AQ10*$I$2*100/(AR10*AP10))<100+AQ10-3.33*AR10*AP10/$I$2,100+AQ10-3.33*AR10*AP10/$I$2,IF((AQ10*$I$2*100/(AR10*AP10))>200,200,(AQ10*$I$2*100/(AR10*AP10))))),"") -> 188.13714 | AU10: =IF(AP10>0,MAX(K10:AO10),"") -> 84 | AV10: =IFERROR(VLOOKUP(A10,Maximos!A:AQ,8+(Precipitacion!$E$2-1)*3,FALSE),"") -> 130.4 | AW10: {=IFERROR( _xlfn.LET( _xlpm.mesNum, E$2, _xlpm.mesTxt, INDEX({"ENERO","FEBRERO","MARZO","ABRIL","MAYO","JUNIO","JULIO","AGOSTO","SEPTIEMBRE","OCTUBRE","NOVIEMBRE","DICIEMBRE"}, _xlpm.mesNum), _xlpm.colIni, MATCH(_xlpm.mesTxt, Maximos!$1:$1, 0), _xlpm.fila, MATCH($A10, Maximos!$A:$A, 0), _xlpm.anio, INDEX(Maximos!$A:$ZZ, _xlpm.fila, _xlpm.colIni+1), _xlpm.dia, INDEX(Maximos!$A:$ZZ, _xlpm.fila, _xlpm.colIni+2), IF(OR(_xlpm.anio="",_xlpm.dia=""), "No aplica", DATE(_xlpm.anio, _xlpm.mesNum, _xlpm.dia)) ), "")} -> 37411 | AX10: =IFERROR(AU10-AV10,"NA") -> -46.4
A11: 28025502 | B11: Aeropuerto Alfonso López | C11: Met_Aeronautica | D11: -73.247667 | E11: 10.436167 | F11: 138 | G11: 20 | H11: 20001 | I11: Cesar | J11: Valledupar | K11: 0 | L11: 0 | M11: 1.1 | N11: 15.2 | O11: 1.3 | P11: 10.8 | Q11: 0.9 | R11: 0.2 | S11: 2.7 | T11: 0 | U11: 0 | V11: 16.2 | W11: 0 | X11: 0 | Y11: 5.2 | Z11: 1.8 | AA11: 0 | AB11: 0 | AC11: 0 | AD11: 1.2 | AE11: 0 | AF11: 0 | AG11: 0 | AH11: 0 | AI11: 0 | AJ11: 0 | AK11: 0 | AL11: 0 | AM11: 0 | AN11: 0 | AP11: =COUNTIF(K11:AO11,">=0") -> 30 | AQ11: =IF(AP11>0,SUM(K11:AO11),"") -> 56.6 | AR11: =IFERROR(VLOOKUP(A11,Climatologia_PP!A:U,9+Precipitacion!$E$2,FALSE),"") -> 88.37037 | AS11: =IFERROR((AQ11/AR11)*100,"") -> 64.048617 | AT11: =IFERROR(IF(AND((AQ11*$I$2*100/(AR11*AP11))>100+3.33*AQ11-AR11*AP11/$I$2,AR11<30),IF(100+3.33*AQ11-AR11*AP11/$I$2>200,200,100+3.33*AQ11-AR11*AP11/$I$2),IF((AQ11*$I$2*100/(AR11*AP11))<100+AQ11-3.33*AR11*AP11/$I$2,100+AQ11-3.33*AR11*AP11/$I$2,IF((AQ11*$I$2*100/(AR11*AP11))>200,200,(AQ11*$I$2*100/(AR11*AP11))))),"") -> 64.048617 | AU11: =IF(AP11>0,MAX(K11:AO11),"") -> 16.2 | AV11: =IFERROR(VLOOKUP(A11,Maximos!A:AQ,8+(Precipitacion!$E$2-1)*3,FALSE),"") -> 74.8 | AW11: {=IFERROR( _xlfn.LET( _xlpm.mesNum, E$2, _xlpm.mesTxt, INDEX({"ENERO","FEBRERO","MARZO","ABRIL","MAYO","JUNIO","JULIO","AGOSTO","SEPTIEMBRE","OCTUBRE","NOVIEMBRE","DICIEMBRE"}, _xlpm.mesNum), _xlpm.colIni, MATCH(_xlpm.mesTxt, Maximos!$1:$1, 0), _xlpm.fila, MATCH($A11, Maximos!$A:$A, 0), _xlpm.anio, INDEX(Maximos!$A:$ZZ, _xlpm.fila, _xlpm.colIni+1), _xlpm.dia, INDEX(Maximos!$A:$ZZ, _xlpm.fila, _xlpm.colIni+2), IF(OR(_xlpm.anio="",_xlpm.dia=""), "No aplica", DATE(_xlpm.anio, _xlpm.mesNum, _xlpm.dia)) ), "")} -> 37413 | AX11: =IFERROR(AU11-AV11,"NA") -> -58.6
A12: 13035501 | B12: Aeropuerto Los Garzones | C12: Met_Aeronautica | D12: -75.825139 | E12: 8.8258333 | F12: 20 | G12: 23 | H12: 23001 | I12: Córdoba | J12: Montería | K12: 0 | L12: 0 | M12: 0.3 | N12: 0 | O12: 0 | P12: 16.8 | Q12: 1.3 | R12: 0.4 | S12: 0.6 | T12: 0 | U12: 0 | V12: 0 | W12: 15.1 | X12: 2.3 | Y12: 14.4 | Z12: 12.7 | AA12: 2.3 | AB12: 1.3 | AC12: 0 | AD12: 0 | AE12: 0 | AF12: 4.8 | AG12: 0 | AH12: 0 | AI12: 2.4 | AJ12: 0 | AK12: 0 | AL12: 0 | AM12: 0 | AN12: 0 | AP12: =COUNTIF(K12:AO12,">=0") -> 30 | AQ12: =IF(AP12>0,SUM(K12:AO12),"") -> 74.7 | AR12: =IFERROR(VLOOKUP(A12,Climatologia_PP!A:U,9+Precipitacion!$E$2,FALSE),"") -> 164.5 | AS12: =IFERROR((AQ12/AR12)*100,"") -> 45.410334 | AT12: =IFERROR(IF(AND((AQ12*$I$2*100/(AR12*AP12))>100+3.33*AQ12-AR12*AP12/$I$2,AR12<30),IF(100+3.33*AQ12-AR12*AP12/$I$2>200,200,100+3.33*AQ12-AR12*AP12/$I$2),IF((AQ12*$I$2*100/(AR12*AP12))<100+AQ12-3.33*AR12*AP12/$I$2,100+AQ12-3.33*AR12*AP12/$I$2,IF((AQ12*$I$2*100/(AR12*AP12))>200,200,(AQ12*$I$2*100/(AR12*AP12))))),"") -> 45.410334 | AU12: =IF(AP12>0,MAX(K12:AO12),"") -> 16.8 | AV12: =IFERROR(VLOOKUP(A12,Maximos!A:AQ,8+(Precipitacion!$E$2-1)*3,FALSE),"") -> 148 | AW12: {=IFERROR( _xlfn.LET( _xlpm.mesNum, E$2, _xlpm.mesTxt, INDEX({"ENERO","FEBRERO","MARZO","ABRIL","MAYO","JUNIO","JULIO","AGOSTO","SEPTIEMBRE","OCTUBRE","NOVIEMBRE","DICIEMBRE"}, _xlpm.mesNum), _xlpm.colIni, MATCH(_xlpm.mesTxt, Maximos!$1:$1, 0), _xlpm.fila, MATCH($A12, Maximos!$A:$A, 0), _xlpm.anio, INDEX(Maximos!$A:$ZZ, _xlpm.fila, _xlpm.colIni+1), _xlpm.dia, INDEX(Maximos!$A:$ZZ, _xlpm.fila, _xlpm.colIni+2), IF(OR(_xlpm.anio="",_xlpm.dia=""), "No aplica", DATE(_xlpm.anio, _xlpm.mesNum, _xlpm.dia)) ), "")} -> 27922 | AX12: =IFERROR(AU12-AV12,"NA") -> -131.2
A13: 23155030 | B13: Aeropuerto Yariguies | C13: Met_Aeronautica | D13: -73.808611 | E13: 7.0263889 | F13: 126 | G13: 68 | H13: 68081 | I13: Santander | J13: Barrancabermeja | K13: 0 | L13: 0 | M13: 72.4 | N13: 1.8 | O13: 0 | P13: 134.6 | Q13: 2.4 | R13: 1.2 | S13: 31 | T13: 0 | U13: 0.4 | V13: 0 | W13: 0 | X13: 0 | Y13: 0 | Z13: 0.5 | AA13: 2.4 | AB13: 36.7 | AC13: 0 | AD13: 52.6 | AE13: 0 | AF13: 0 | AG13: 0 | AH13: 0 | AI13: 0 | AJ13: 0 | AK13: 0 | AL13: 0 | AM13: 0 | AN13: 0 | AP13: =COUNTIF(K13:AO13,">=0") -> 30 | AQ13: =IF(AP13>0,SUM(K13:AO13),"") -> 336 | AR13: =IFERROR(VLOOKUP(A13,Climatologia_PP!A:U,9+Precipitacion!$E$2,FALSE),"") -> 256.56786 | AS13: =IFERROR((AQ13/AR13)*100,"") -> 130.95951 | AT13: =IFERROR(IF(AND((AQ13*$I$2*100/(AR13*AP13))>100+3.33*AQ13-AR13*AP13/$I$2,AR13<30),IF(100+3.33*AQ13-AR13*AP13/$I$2>200,200,100+3.33*AQ13-AR13*AP13/$I$2),IF((AQ13*$I$2*100/(AR13*AP13))<100+AQ13-3.33*AR13*AP13/$I$2,100+AQ13-3.33*AR13*AP13/$I$2,IF((AQ13*$I$2*100/(AR13*AP13))>200,200,(AQ13*$I$2*100/(AR13*AP13))))),"") -> 130.95951 | AU13: =IF(AP13>0,MAX(K13:AO13),"") -> 134.6 | AV13: =IFERROR(VLOOKUP(A13,Maximos!A:AQ,8+(Precipitacion!$E$2-1)*3,FALSE),"") -> 129.2 | AW13: {=IFERROR( _xlfn.LET( _xlpm.mesNum, E$2, _xlpm.mesTxt, INDEX({"ENERO","FEBRERO","MARZO","ABRIL","MAYO","JUNIO","JULIO","AGOSTO","SEPTIEMBRE","OCTUBRE","NOVIEMBRE","DICIEMBRE"}, _xlpm.mesNum), _xlpm.colIni, MATCH(_xlpm.mesTxt, Maximos!$1:$1, 0), _xlpm.fila, MATCH($A13, Maximos!$A:$A, 0), _xlpm.anio, INDEX(Maximos!$A:$ZZ, _xlpm.fila, _xlpm.colIni+1), _xlpm.dia, INDEX(Maximos!$A:$ZZ, _xlpm.fila, _xlpm.colIni+2), IF(OR(_xlpm.anio="",_xlpm.dia=""), "No aplica", DATE(_xlpm.anio, _xlpm.mesNum, _xlpm.dia)) ), "")} -> 43627 | AX13: =IFERROR(AU13-AV13,"NA") -> 5.4
A14: 23195502 | B14: Aeropuerto Palonegro | C14: Met_Aeronautica | D14: -73.184528 | E14: 7.1214722 | F14: 1189 | G14: 68 | H14: 68406 | I14: Santander | J14: Lebrija | K14: 0 | L14: 19.3 | M14: 2.1 | N14: 2.1 | O14: 2.3 | P14: 13.3 | Q14: 1.1 | R14: 2.8 | S14: 0 | T14: 0 | U14: 0.2 | V14: 0 | W14: 0 | X14: 0 | Y14: 3.7 | Z14: 0 | AA14: 23.5 | AB14: 0 | AC14: 0 | AD14: 0 | AE14: 0 | AF14: 0 | AG14: 0 | AH14: 0 | AI14: 0 | AJ14: 0 | AK14: 0 | AL14: 0 | AM14: 0.8 | AN14: 19.7 | AP14: =COUNTIF(K14:AO14,">=0") -> 30 | AQ14: =IF(AP14>0,SUM(K14:AO14),"") -> 90.9 | AR14: =IFERROR(VLOOKUP(A14,Climatologia_PP!A:U,9+Precipitacion!$E$2,FALSE),"") -> 74.303704 | AS14: =IFERROR((AQ14/AR14)*100,"") -> 122.33576 | AT14: =IFERROR(IF(AND((AQ14*$I$2*100/(AR14*AP14))>100+3.33*AQ14-AR14*AP14/$I$2,AR14<30),IF(100+3.33*AQ14-AR14*AP14/$I$2>200,200,100+3.33*AQ14-AR14*AP14/$I$2),IF((AQ14*$I$2*100/(AR14*AP14))<100+AQ14-3.33*AR14*AP14/$I$2,100+AQ14-3.33*AR14*AP14/$I$2,IF((AQ14*$I$2*100/(AR14*AP14))>200,200,(AQ14*$I$2*100/(AR14*AP14))))),"") -> 122.33576 | AU14: =IF(AP14>0,MAX(K14:AO14),"") -> 23.5 | AV14: =IFERROR(VLOOKUP(A14,Maximos!A:AQ,8+(Precipitacion!$E$2-1)*3,FALSE),"") -> 69.7 | AW14: {=IFERROR( _xlfn.LET( _xlpm.mesNum, E$2, _xlpm.mesTxt, INDEX({"ENERO","FEBRERO","MARZO","ABRIL","MAYO","JUNIO","JULIO","AGOSTO","SEPTIEMBRE","OCTUBRE","NOVIEMBRE","DICIEMBRE"}, _xlpm.mesNum), _xlpm.colIni, MATCH(_xlpm.mesTxt, Maximos!$1:$1, 0), _xlpm.fila, MATCH($A14, Maximos!$A:$A, 0), _xlpm.anio, INDEX(Maximos!$A:$ZZ, _xlpm.fila, _xlpm.colIni+1), _xlpm.dia, INDEX(Maximos!$A:$ZZ, _xlpm.fila, _xlpm.colIni+2), IF(OR(_xlpm.anio="",_xlpm.dia=""), "No aplica", DATE(_xlpm.anio, _xlpm.mesNum, _xlpm.dia)) ), "")} -> 39973 | AX14: =IFERROR(AU14-AV14,"NA") -> -46.2
A15: 16015010 | B15: Aeropuerto Camilo Daza | C15: Met_Aeronautica | D15: -72.509167 | E15: 7.9302778 | F15: 250 | G15: 54 | H15: 54001 | I15: Norte de Santander | J15: San José De Cúcuta | K15: 0 | L15: 0 | M15: 0 | N15: 23.5 | O15: 0 | P15: 0 | Q15: 1.7 | R15: 0 | S15: 0 | T15: 0 | U15: 0 | V15: 0 | W15: 0 | X15: 0 | Y15: 0 | Z15: 0.2 | AA15: 0 | AB15: 0 | AC15: 0 | AD15: 0 | AE15: 0 | AF15: 0.1 | AG15: 0 | AH15: 0 | AI15: 0 | AJ15: 0 | AK15: 0 | AL15: 0 | AM15: 0 | AN15: 0.1 | AP15: =COUNTIF(K15:AO15,">=0") -> 30 | AQ15: =IF(AP15>0,SUM(K15:AO15),"") -> 25.6 | AR15: =IFERROR(VLOOKUP(A15,Climatologia_PP!A:U,9+Precipitacion!$E$2,FALSE),"") -> 42.536 | AS15: =IFERROR((AQ15/AR15)*100,"") -> 60.184314 | AT15: =IFERROR(IF(AND((AQ15*$I$2*100/(AR15*AP15))>100+3.33*AQ15-AR15*AP15/$I$2,AR15<30),IF(100+3.33*AQ15-AR15*AP15/$I$2>200,200,100+3.33*AQ15-AR15*AP15/$I$2),IF((AQ15*$I$2*100/(AR15*AP15))<100+AQ15-3.33*AR15*AP15/$I$2,100+AQ15-3.33*AR15*AP15/$I$2,IF((AQ15*$I$2*100/(AR15*AP15))>200,200,(AQ15*$I$2*100/(AR15*AP15))))),"") -> 60.184314 | AU15: =IF(AP15>0,MAX(K15:AO15),"") -> 23.5 | AV15: =IFERROR(VLOOKUP(A15,Maximos!A:AQ,8+(Precipitacion!$E$2-1)*3,FALSE),"") -> 74.3 | AW15: {=IFERROR( _xlfn.LET( _xlpm.mesNum, E$2, _xlpm.mesTxt, INDEX({"ENERO","FEBRERO","MARZO","ABRIL","MAYO","JUNIO","JULIO","AGOSTO","SEPTIEMBRE","OCTUBRE","NOVIEMBRE","DICIEMBRE"}, _xlpm.mesNum), _xlpm.colIni, MATCH(_xlpm.mesTxt, Maximos!$1:$1, 0), _xlpm.fila, MATCH($A15, Maximos!$A:$A, 0), _xlpm.anio, INDEX(Maximos!$A:$ZZ, _xlpm.fila, _xlpm.colIni+1), _xlpm.dia, INDEX(Maximos!$A:$ZZ, _xlpm.fila, _xlpm.colIni+2), IF(OR(_xlpm.anio="",_xlpm.dia=""), "No aplica", DATE(_xlpm.anio, _xlpm.mesNum, _xlpm.dia)) ), "")} -> 38509 | AX15: =IFERROR(AU15-AV15,"NA") -> -50.8
A16: 12015070 | B16: Aeropuerto Los Cedros | C16: Met_Aeronautica | D16: -76.717889 | E16: 7.8163889 | F16: 41 | G16: 5 | H16: 5147 | I16: Antioquia | J16: Carepa | K16: 0 | L16: 29.1 | M16: 0 | N16: 2 | O16: 1.1 | P16: 3 | Q16: 0 | R16: 1.1 | S16: 0 | T16: 0 | U16: 0 | V16: 1.1 | W16: 0.4 | X16: 6.1 | Y16: 4.8 | Z16: 87.5 | AA16: 1.6 | AB16: 0.2 | AC16: 22.9 | AD16: 10.6 | AE16: 10.3 | AF16: 118.3 | AG16: 0.2 | AH16: 2.3 | AI16: 8.1 | AJ16: 0.4 | AK16: 0 | AL16: 13.1 | AM16: 0 | AN16: 6.2 | AP16: =COUNTIF(K16:AO16,">=0") -> 30 | AQ16: =IF(AP16>0,SUM(K16:AO16),"") -> 330.4 | AR16: =IFERROR(VLOOKUP(A16,Climatologia_PP!A:U,9+Precipitacion!$E$2,FALSE),"") -> 327.45714 | AS16: =IFERROR((AQ16/AR16)*100,"") -> 100.8987 | AT16: =IFERROR(IF(AND((AQ16*$I$2*100/(AR16*AP16))>100+3.33*AQ16-AR16*AP16/$I$2,AR16<30),IF(100+3.33*AQ16-AR16*AP16/$I$2>200,200,100+3.33*AQ16-AR16*AP16/$I$2),IF((AQ16*$I$2*100/(AR16*AP16))<100+AQ16-3.33*AR16*AP16/$I$2,100+AQ16-3.33*AR16*AP16/$I$2,IF((AQ16*$I$2*100/(AR16*AP16))>200,200,(AQ16*$I$2*100/(AR16*AP16))))),"") -> 100.8987 | AU16: =IF(AP16>0,MAX(K16:AO16),"") -> 118.3 | AV16: =IFERROR(VLOOKUP(A16,Maximos!A:AQ,8+(Precipitacion!$E$2-1)*3,FALSE),"") -> 217 | AW16: {=IFERROR( _xlfn.LET( _xlpm.mesNum, E$2, _xlpm.mesTxt, INDEX({"ENERO","FEBRERO","MARZO","ABRIL","MAYO","JUNIO","JULIO","AGOSTO","SEPTIEMBRE","OCTUBRE","NOVIEMBRE","DICIEMBRE"}, _xlpm.mesNum), _xlpm.colIni, MATCH(_xlpm.mesTxt, Maximos!$1:$1, 0), _xlpm.fila, MATCH($A16, Maximos!$A:$A, 0), _xlpm.anio, INDEX(Maximos!$A:$ZZ, _xlpm.fila, _xlpm.colIni+1), _xlpm.dia, INDEX(Maximos!$A:$ZZ, _xlpm.fila, _xlpm.colIni+2), IF(OR(_xlpm.anio="",_xlpm.dia=""), "No aplica", DATE(_xlpm.anio, _xlpm.mesNum, _xlpm.dia)) ), "")} -> 41799 | AX16: =IFERROR(AU16-AV16,"NA") -> -98.7
A17: 27015330 | B17: Aeropuerto Olaya Herrera - AUT | C17: Met_Aeronautica | D17: -75.59 | E17: 6.22 | F17: 1490 | G17: 5 | H17: 5001 | I17: Antioquia | J17: Medellín | AP17: =COUNTIF(K17:AO17,">=0") -> 0 | AQ17: =IF(AP17>0,SUM(K17:AO17),"") | AR17: =IFERROR(VLOOKUP(A17,Climatologia_PP!A:U,9+Precipitacion!$E$2,FALSE),"") -> 144.96 | AS17: =IFERROR((AQ17/AR17)*100,"") | AT17: =IFERROR(IF(AND((AQ17*$I$2*100/(AR17*AP17))>100+3.33*AQ17-AR17*AP17/$I$2,AR17<30),IF(100+3.33*AQ17-AR17*AP17/$I$2>200,200,100+3.33*AQ17-AR17*AP17/$I$2),IF((AQ17*$I$2*100/(AR17*AP17))<100+AQ17-3.33*AR17*AP17/$I$2,100+AQ17-3.33*AR17*AP17/$I$2,IF((AQ17*$I$2*100/(AR17*AP17))>200,200,(AQ17*$I$2*100/(AR17*AP17))))),"") | AU17: =IF(AP17>0,MAX(K17:AO17),"") | AV17: =IFERROR(VLOOKUP(A17,Maximos!A:AQ,8+(Precipitacion!$E$2-1)*3,FALSE),"") -> 69.3 | AW17: {=IFERROR( _xlfn.LET( _xlpm.mesNum, E$2, _xlpm.mesTxt, INDEX({"ENERO","FEBRERO","MARZO","ABRIL","MAYO","JUNIO","JULIO","AGOSTO","SEPTIEMBRE","OCTUBRE","NOVIEMBRE","DICIEMBRE"}, _xlpm.mesNum), _xlpm.colIni, MATCH(_xlpm.mesTxt, Maximos!$1:$1, 0), _xlpm.fila, MATCH($A17, Maximos!$A:$A, 0), _xlpm.anio, INDEX(Maximos!$A:$ZZ, _xlpm.fila, _xlpm.colIni+1), _xlpm.dia, INDEX(Maximos!$A:$ZZ, _xlpm.fila, _xlpm.colIni+2), IF(OR(_xlpm.anio="",_xlpm.dia=""), "No aplica", DATE(_xlpm.anio, _xlpm.mesNum, _xlpm.dia)) ), "")} -> 45451 | AX17: =IFERROR(AU17-AV17,"NA") -> NA
A18: 23085270 | B18: Aeropuerto José María Córdova - AUT | C18: Met_Aeronautica | D18: -75.43 | E18: 6.17 | F18: 2157 | G18: 5 | H18: 5615 | I18: Antioquia | J18: Rionegro | K18: 0 | L18: 0 | M18: 7.3 | N18: 0.9 | O18: 0.5 | P18: 7.1 | Q18: 27.7 | R18: 18.6 | S18: 1.5 | T18: 0 | U18: 0 | V18: 0 | W18: 5.1 | X18: 0 | Y18: 1.8 | Z18: 0 | AA18: 11.1 | AB18: 20.6 | AC18: 9.2 | AD18: 11.6 | AE18: 1.7 | AF18: 27.8 | AG18: 0 | AH18: 0 | AI18: 0 | AJ18: 0 | AK18: 0 | AL18: 0 | AM18: 0 | AN18: 0 | AP18: =COUNTIF(K18:AO18,">=0") -> 30 | AQ18: =IF(AP18>0,SUM(K18:AO18),"") -> 152.5 | AR18: =IFERROR(VLOOKUP(A18,Climatologia_PP!A:U,9+Precipitacion!$E$2,FALSE),"") -> 173.45517 | AS18: =IFERROR((AQ18/AR18)*100,"") -> 87.918969 | AT18: =IFERROR(IF(AND((AQ18*$I$2*100/(AR18*AP18))>100+3.33*AQ18-AR18*AP18/$I$2,AR18<30),IF(100+3.33*AQ18-AR18*AP18/$I$2>200,200,100+3.33*AQ18-AR18*AP18/$I$2),IF((AQ18*$I$2*100/(AR18*AP18))<100+AQ18-3.33*AR18*AP18/$I$2,100+AQ18-3.33*AR18*AP18/$I$2,IF((AQ18*$I$2*100/(AR18*AP18))>200,200,(AQ18*$I$2*100/(AR18*AP18))))),"") -> 87.918969 | AU18: =IF(AP18>0,MAX(K18:AO18),"") -> 27.8 | AV18: =IFERROR(VLOOKUP(A18,Maximos!A:AQ,8+(Precipitacion!$E$2-1)*3,FALSE),"") -> 72.6 | AW18: {=IFERROR( _xlfn.LET( _xlpm.mesNum, E$2, _xlpm.mesTxt, INDEX({"ENERO","FEBRERO","MARZO","ABRIL","MAYO","JUNIO","JULIO","AGOSTO","SEPTIEMBRE","OCTUBRE","NOVIEMBRE","DICIEMBRE"}, _xlpm.mesNum), _xlpm.colIni, MATCH(_xlpm.mesTxt, Maximos!$1:$1, 0), _xlpm.fila, MATCH($A18, Maximos!$A:$A, 0), _xlpm.anio, INDEX(Maximos!$A:$ZZ, _xlpm.fila, _xlpm.colIni+1), _xlpm.dia, INDEX(Maximos!$A:$ZZ, _xlpm.fila, _xlpm.colIni+2), IF(OR(_xlpm.anio="",_xlpm.dia=""), "No aplica", DATE(_xlpm.anio, _xlpm.mesNum, _xlpm.dia)) ), "")} -> 34857 | AX18: =IFERROR(AU18-AV18,"NA") -> -44.8
A19: 26135040 | B19: Aeropuerto Matecaña | C19: Met_Aeronautica | D19: -75.737222 | E19: 4.8158611 | F19: 1342 | G19: 66 | H19: 66001 | I19: Risaralda | J19: Pereira | K19: 0 | L19: 0 | M19: 7.8 | N19: 24 | O19: 5.4 | P19: 6.2 | Q19: 12.7 | R19: 1.8 | S19: 2.7 | T19: 0.4 | U19: 0 | V19: 0 | W19: 7.5 | X19: 0 | Y19: 1.8 | Z19: 0.8 | AA19: 0.5 | AB19: 0.6 | AC19: 0 | AD19: 0 | AE19: 0 | AF19: 6.2 | AG19: 31 | AH19: 0 | AI19: 0 | AJ19: 0 | AK19: 0 | AL19: 0.3 | AM19: 0 | AN19: 0 | AP19: =COUNTIF(K19:AO19,">=0") -> 30 | AQ19: =IF(AP19>0,SUM(K19:AO19),"") -> 109.7 | AR19: =IFERROR(VLOOKUP(A19,Climatologia_PP!A:U,9+Precipitacion!$E$2,FALSE),"") -> 199.31034 | AS19: =IFERROR((AQ19/AR19)*100,"") -> 55.039792 | AT19: =IFERROR(IF(AND((AQ19*$I$2*100/(AR19*AP19))>100+3.33*AQ19-AR19*AP19/$I$2,AR19<30),IF(100+3.33*AQ19-AR19*AP19/$I$2>200,200,100+3.33*AQ19-AR19*AP19/$I$2),IF((AQ19*$I$2*100/(AR19*AP19))<100+AQ19-3.33*AR19*AP19/$I$2,100+AQ19-3.33*AR19*AP19/$I$2,IF((AQ19*$I$2*100/(AR19*AP19))>200,200,(AQ19*$I$2*100/(AR19*AP19))))),"") -> 55.039792 | AU19: =IF(AP19>0,MAX(K19:AO19),"") -> 31 | AV19: =IFERROR(VLOOKUP(A19,Maximos!A:AQ,8+(Precipitacion!$E$2-1)*3,FALSE),"") -> 103.3 | AW19: {=IFERROR( _xlfn.LET( _xlpm.mesNum, E$2, _xlpm.mesTxt, INDEX({"ENERO","FEBRERO","MARZO","ABRIL","MAYO","JUNIO","JULIO","AGOSTO","SEPTIEMBRE","OCTUBRE","NOVIEMBRE","DICIEMBRE"}, _xlpm.mesNum), _xlpm.colIni, MATCH(_xlpm.mesTxt, Maximos!$1:$1, 0), _xlpm.fila, MATCH($A19, Maximos!$A:$A, 0), _xlpm.anio, INDEX(Maximos!$A:$ZZ, _xlpm.fila, _xlpm.colIni+1), _xlpm.dia, INDEX(Maximos!$A:$ZZ, _xlpm.fila, _xlpm.colIni+2), IF(OR(_xlpm.anio="",_xlpm.dia=""), "No aplica", DATE(_xlpm.anio, _xlpm.mesNum, _xlpm.dia)) ), "")} -> 36312 | AX19: =IFERROR(AU19-AV19,"NA") -> -72.3
A20: 26125061 | B20: Aeropuerto El Edén - AUT | C20: Met_Aeronautica | D20: -75.766389 | E20: 4.4547222 | F20: 1229 | G20: 63 | H20: 63001 | I20: Quindío | J20: Armenia | K20: 0 | L20: 0 | M20: 3.2 | N20: 6.9 | O20: 1.3 | P20: 5.3 | Q20: 27.8 | R20: 6.5 | S20: 0 | T20: 0 | U20: 0.1 | V20: 0 | W20: 0.2 | X20: 0 | Y20: 0.3 | Z20: 18 | AA20: 13.7 | AB20: 0.8 | AC20: 0.2 | AD20: 0 | AE20: 1 | AF20: 0 | AG20: 13.4 | AH20: 0 | AI20: 0 | AJ20: 0 | AK20: 0 | AL20: 0 | AM20: 0 | AN20: 0 | AP20: =COUNTIF(K20:AO20,">=0") -> 30 | AQ20: =IF(AP20>0,SUM(K20:AO20),"") -> 98.7 | AR20: =IFERROR(VLOOKUP(A20,Climatologia_PP!A:U,9+Precipitacion!$E$2,FALSE),"") -> 152.2037 | AS20: =IFERROR((AQ20/AR20)*100,"") -> 64.847305 | AT20: =IFERROR(IF(AND((AQ20*$I$2*100/(AR20*AP20))>100+3.33*AQ20-AR20*AP20/$I$2,AR20<30),IF(100+3.33*AQ20-AR20*AP20/$I$2>200,200,100+3.33*AQ20-AR20*AP20/$I$2),IF((AQ20*$I$2*100/(AR20*AP20))<100+AQ20-3.33*AR20*AP20/$I$2,100+AQ20-3.33*AR20*AP20/$I$2,IF((AQ20*$I$2*100/(AR20*AP20))>200,200,(AQ20*$I$2*100/(AR20*AP20))))),"") -> 64.847305 | AU20: =IF(AP20>0,MAX(K20:AO20),"") -> 27.8 | AV20: =IFERROR(VLOOKUP(A20,Maximos!A:AQ,8+(Precipitacion!$E$2-1)*3,FALSE),"") -> 144.6 | AW20: {=IFERROR( _xlfn.LET( _xlpm.mesNum, E$2, _xlpm.mesTxt, INDEX({"ENERO","FEBRERO","MARZO","ABRIL","MAYO","JUNIO","JULIO","AGOSTO","SEPTIEMBRE","OCTUBRE","NOVIEMBRE","DICIEMBRE"}, _xlpm.mesNum), _xlpm.colIni, MATCH(_xlpm.mesTxt, Maximos!$1:$1, 0), _xlpm.fila, MATCH($A20, Maximos!$A:$A, 0), _xlpm.anio, INDEX(Maximos!$A:$ZZ, _xlpm.fila, _xlpm.colIni+1), _xlpm.dia, INDEX(Maximos!$A:$ZZ, _xlpm.fila, _xlpm.colIni+2), IF(OR(_xlpm.anio="",_xlpm.dia=""), "No aplica", DATE(_xlpm.anio, _xlpm.mesNum, _xlpm.dia)) ), "")} -> 39601 | AX20: =IFERROR(AU20-AV20,"NA") -> -116.8
A21: 21245040 | B21: Aeropuerto Perales | C21: Met_Aeronautica | D21: -75.139417 | E21: 4.4241389 | F21: 943 | G21: 73 | H21: 73001 | I21: Tolima | J21: Ibagué | K21: 0 | L21: 1.2 | M21: 0 | N21: 2.2 | O21: 6.3 | P21: 0 | Q21: 1.3 | R21: 55.7 | S21: 0 | T21: 0 | U21: 0 | V21: 0.1 | W21: 0 | X21: 0.8 | Y21: 0 | Z21: 0.3 | AA21: 0.9 | AB21: 0.7 | AC21: 0 | AD21: 2.2 | AE21: 0 | AF21: 0 | AG21: 5.9 | AH21: 4.3 | AI21: 0 | AJ21: 0 | AK21: 0 | AL21: 0 | AM21: 0 | AN21: 0 | AP21: =COUNTIF(K21:AO21,">=0") -> 30 | AQ21: =IF(AP21>0,SUM(K21:AO21),"") -> 81.9 | AR21: =IFERROR(VLOOKUP(A21,Climatologia_PP!A:U,9+Precipitacion!$E$2,FALSE),"") -> 99.066667 | AS21: =IFERROR((AQ21/AR21)*100,"") -> 82.671602 | AT21: =IFERROR(IF(AND((AQ21*$I$2*100/(AR21*AP21))>100+3.33*AQ21-AR21*AP21/$I$2,AR21<30),IF(100+3.33*AQ21-AR21*AP21/$I$2>200,200,100+3.33*AQ21-AR21*AP21/$I$2),IF((AQ21*$I$2*100/(AR21*AP21))<100+AQ21-3.33*AR21*AP21/$I$2,100+AQ21-3.33*AR21*AP21/$I$2,IF((AQ21*$I$2*100/(AR21*AP21))>200,200,(AQ21*$I$2*100/(AR21*AP21))))),"") -> 82.671602 | AU21: =IF(AP21>0,MAX(K21:AO21),"") -> 55.7 | AV21: =IFERROR(VLOOKUP(A21,Maximos!A:AQ,8+(Precipitacion!$E$2-1)*3,FALSE),"") -> 90.3 | AW21: {=IFERROR( _xlfn.LET( _xlpm.mesNum, E$2, _xlpm.mesTxt, INDEX({"ENERO","FEBRERO","MARZO","ABRIL","MAYO","JUNIO","JULIO","AGOSTO","SEPTIEMBRE","OCTUBRE","NOVIEMBRE","DICIEMBRE"}, _xlpm.mesNum), _xlpm.colIni, MATCH(_xlpm.mesTxt, Maximos!$1:$1, 0), _xlpm.fila, MATCH($A21, Maximos!$A:$A, 0), _xlpm.anio, INDEX(Maximos!$A:$ZZ, _xlpm.fila, _xlpm.colIni+1), _xlpm.dia, INDEX(Maximos!$A:$ZZ, _xlpm.fila, _xlpm.colIni+2), IF(OR(_xlpm.anio="",_xlpm.dia=""), "No aplica", DATE(_xlpm.anio, _xlpm.mesNum, _xlpm.dia)) ), "")} -> 26817 | AX21: =IFERROR(AU21-AV21,"NA") -> -34.6
A22: 21205791 | B22: Aeropuerto El Dorado Catam - AUT | C22: Met_Aeronautica | D22: -74.150667 | E22: 4.7055833 | F22: 2547 | G22: 11 | H22: 11001 | I22: Bogotá, D.C. | J22: Bogotá, D.C. | K22: 0.1 | L22: 1.16 | M22: 0 | N22: 1.6 | O22: 3.7 | P22: 0 | Q22: 11.1 | R22: 11.8 | S22: 10.2 | T22: 0 | U22: 0 | V22: 0 | W22: 0 | X22: 0 | Y22: 0.7 | Z22: 0.8 | AA22: 0.479 | AB22: 4.1 | AC22: 0.4 | AD22: 0.2 | AE22: 0 | AF22: 0 | AG22: 0.3 | AH22: 0 | AI22: 0 | AJ22: 0 | AK22: 0.1 | AL22: 0 | AM22: 0.2 | AN22: 0 | AP22: =COUNTIF(K22:AO22,">=0") -> 30 | AQ22: =IF(AP22>0,SUM(K22:AO22),"") -> 46.939 | AR22: =IFERROR(VLOOKUP(A22,Climatologia_PP!A:U,9+Precipitacion!$E$2,FALSE),"") -> 57.425 | AS22: =IFERROR((AQ22/AR22)*100,"") -> 81.73966 | AT22: =IFERROR(IF(AND((AQ22*$I$2*100/(AR22*AP22))>100+3.33*AQ22-AR22*AP22/$I$2,AR22<30),IF(100+3.33*AQ22-AR22*AP22/$I$2>200,200,100+3.33*AQ22-AR22*AP22/$I$2),IF((AQ22*$I$2*100/(AR22*AP22))<100+AQ22-3.33*AR22*AP22/$I$2,100+AQ22-3.33*AR22*AP22/$I$2,IF((AQ22*$I$2*100/(AR22*AP22))>200,200,(AQ22*$I$2*100/(AR22*AP22))))),"") -> 81.73966 | AU22: =IF(AP22>0,MAX(K22:AO22),"") -> 11.8 | AV22: =IFERROR(VLOOKUP(A22,Maximos!A:AQ,8+(Precipitacion!$E$2-1)*3,FALSE),"") -> 35.2 | AW22: {=IFERROR( _xlfn.LET( _xlpm.mesNum, E$2, _xlpm.mesTxt, INDEX({"ENERO","FEBRERO","MARZO","ABRIL","MAYO","JUNIO","JULIO","AGOSTO","SEPTIEMBRE","OCTUBRE","NOVIEMBRE","DICIEMBRE"}, _xlpm.mesNum), _xlpm.colIni, MATCH(_xlpm.mesTxt, Maximos!$1:$1, 0), _xlpm.fila, MATCH($A22, Maximos!$A:$A, 0), _xlpm.anio, INDEX(Maximos!$A:$ZZ, _xlpm.fila, _xlpm.colIni+1), _xlpm.dia, INDEX(Maximos!$A:$ZZ, _xlpm.fila, _xlpm.colIni+2), IF(OR(_xlpm.anio="",_xlpm.dia=""), "No aplica", DATE(_xlpm.anio, _xlpm.mesNum, _xlpm.dia)) ), "")} -> 38875 | AX22: =IFERROR(AU22-AV22,"NA") -> -23.4
A23: 26075040 | B23: Aeropuerto Alfonso Bonilla | C23: Met_Aeronautica | D23: -76.386639 | E23: 3.5366889 | F23: 970 | G23: 76 | H23: 76520 | I23: Valle del Cauca | J23: Palmira | K23: 0 | L23: 0 | M23: 4.2 | N23: 3.6 | O23: 0.3 | P23: 0 | Q23: 0 | R23: 0 | S23: 4 | T23: 0 | U23: 0 | V23: 0 | W23: 0 | X23: 1.1 | Y23: 1.9 | Z23: 0.1 | AA23: 0.8 | AB23: 1 | AC23: 0 | AD23: 18.4 | AE23: 0 | AF23: 0 | AG23: 0.5 | AH23: 0 | AI23: 0 | AJ23: 0 | AK23: 0 | AL23: 0.6 | AM23: 0 | AN23: 0 | AP23: =COUNTIF(K23:AO23,">=0") -> 30 | AQ23: =IF(AP23>0,SUM(K23:AO23),"") -> 36.5 | AR23: =IFERROR(VLOOKUP(A23,Climatologia_PP!A:U,9+Precipitacion!$E$2,FALSE),"") -> 49.664286 | AS23: =IFERROR((AQ23/AR23)*100,"") -> 73.493456 | AT23: =IFERROR(IF(AND((AQ23*$I$2*100/(AR23*AP23))>100+3.33*AQ23-AR23*AP23/$I$2,AR23<30),IF(100+3.33*AQ23-AR23*AP23/$I$2>200,200,100+3.33*AQ23-AR23*AP23/$I$2),IF((AQ23*$I$2*100/(AR23*AP23))<100+AQ23-3.33*AR23*AP23/$I$2,100+AQ23-3.33*AR23*AP23/$I$2,IF((AQ23*$I$2*100/(AR23*AP23))>200,200,(AQ23*$I$2*100/(AR23*AP23))))),"") -> 73.493456 | AU23: =IF(AP23>0,MAX(K23:AO23),"") -> 18.4 | AV23: =IFERROR(VLOOKUP(A23,Maximos!A:AQ,8+(Precipitacion!$E$2-1)*3,FALSE),"") -> 72.2 | AW23: {=IFERROR( _xlfn.LET( _xlpm.mesNum, E$2, _xlpm.mesTxt, INDEX({"ENERO","FEBRERO","MARZO","ABRIL","MAYO","JUNIO","JULIO","AGOSTO","SEPTIEMBRE","OCTUBRE","NOVIEMBRE","DICIEMBRE"}, _xlpm.mesNum), _xlpm.colIni, MATCH(_xlpm.mesTxt, Maximos!$1:$1, 0), _xlpm.fila, MATCH($A23, Maximos!$A:$A, 0), _xlpm.anio, INDEX(Maximos!$A:$ZZ, _xlpm.fila, _xlpm.colIni+1), _xlpm.dia, INDEX(Maximos!$A:$ZZ, _xlpm.fila, _xlpm.colIni+2), IF(OR(_xlpm.anio="",_xlpm.dia=""), "No aplica", DATE(_xlpm.anio, _xlpm.mesNum, _xlpm.dia)) ), "")} -> 44361 | AX23: =IFERROR(AU23-AV23,"NA") -> -53.8
A24: 21115020 | B24: Aeropuerto Benito Salas | C24: Met_Aeronautica | D24: -75.293056 | E24: 2.94875 | F24: 439 | G24: 41 | H24: 41001 | I24: Huila | J24: Neiva | K24: 0 | L24: 0.9 | M24: 1.9 | N24: 0 | O24: 0.5 | P24: 0 | Q24: 0.4 | R24: 29.2 | S24: 35.4 | T24: 6.3 | U24: 0 | V24: 0 | W24: 0.2 | X24: 11.1 | Y24: 10.2 | Z24: 0.6 | AA24: 0 | AB24: 0 | AC24: 0 | AD24: 0.2 | AE24: 0 | AF24: 0 | AG24: 0.3 | AH24: 0.5 | AI24: 0 | AJ24: 2.3 | AK24: 0 | AL24: 0 | AM24: 0 | AN24: 0.6 | AP24: =COUNTIF(K24:AO24,">=0") -> 30 | AQ24: =IF(AP24>0,SUM(K24:AO24),"") -> 100.6 | AR24: =IFERROR(VLOOKUP(A24,Climatologia_PP!A:U,9+Precipitacion!$E$2,FALSE),"") -> 37.716667 | AS24: =IFERROR((AQ24/AR24)*100,"") -> 266.72559 | AT24: =IFERROR(IF(AND((AQ24*$I$2*100/(AR24*AP24))>100+3.33*AQ24-AR24*AP24/$I$2,AR24<30),IF(100+3.33*AQ24-AR24*AP24/$I$2>200,200,100+3.33*AQ24-AR24*AP24/$I$2),IF((AQ24*$I$2*100/(AR24*AP24))<100+AQ24-3.33*AR24*AP24/$I$2,100+AQ24-3.33*AR24*AP24/$I$2,IF((AQ24*$I$2*100/(AR24*AP24))>200,200,(AQ24*$I$2*100/(AR24*AP24))))),"") -> 200 | AU24: =IF(AP24>0,MAX(K24:AO24),"") -> 35.4 | AV24: =IFERROR(VLOOKUP(A24,Maximos!A:AQ,8+(Precipitacion!$E$2-1)*3,FALSE),"") -> 80.1 | AW24: {=IFERROR( _xlfn.LET( _xlpm.mesNum, E$2, _xlpm.mesTxt, INDEX({"ENERO","FEBRERO","MARZO","ABRIL","MAYO","JUNIO","JULIO","AGOSTO","SEPTIEMBRE","OCTUBRE","NOVIEMBRE","DICIEMBRE"}, _xlpm.mesNum), _xlpm.colIni, MATCH(_xlpm.mesTxt, Maximos!$1:$1, 0), _xlpm.fila, MATCH($A24, Maximos!$A:$A, 0), _xlpm.anio, INDEX(Maximos!$A:$ZZ, _xlpm.fila, _xlpm.colIni+1), _xlpm.dia, INDEX(Maximos!$A:$ZZ, _xlpm.fila, _xlpm.colIni+2), IF(OR(_xlpm.anio="",_xlpm.dia=""), "No aplica", DATE(_xlpm.anio, _xlpm.mesNum, _xlpm.dia)) ), "")} -> 45831 | AX24: =IFERROR(AU24-AV24,"NA") -> -44.7
A25: 52045020 | B25: Aeropuerto Antonio Nariño | C25: Met_Aeronautica | D25: -77.290861 | E25: 1.3940833 | F25: 1796 | G25: 52 | H25: 52240 | I25: Nariño | J25: Chachagüí | K25: 0 | L25: 0 | M25: 2.1 | N25: 28.8 | O25: 0.1 | P25: 0 | Q25: 2.3 | R25: 15.2 | S25: 0.2 | T25: 0 | U25: 0 | V25: 1.8 | W25: 0 | X25: 0 | Y25: 1.9 | Z25: 0 | AA25: 0 | AB25: 0 | AC25: 0 | AD25: 0 | AE25: 0 | AF25: 0 | AG25: 0 | AH25: 0 | AI25: 0 | AJ25: 0.6 | AK25: 0 | AL25: 0 | AM25: 0 | AN25: 0 | AP25: =COUNTIF(K25:AO25,">=0") -> 30 | AQ25: =IF(AP25>0,SUM(K25:AO25),"") -> 53 | AR25: =IFERROR(VLOOKUP(A25,Climatologia_PP!A:U,9+Precipitacion!$E$2,FALSE),"") -> 55.437931 | AS25: =IFERROR((AQ25/AR25)*100,"") -> 95.602413 | AT25: =IFERROR(IF(AND((AQ25*$I$2*100/(AR25*AP25))>100+3.33*AQ25-AR25*AP25/$I$2,AR25<30),IF(100+3.33*AQ25-AR25*AP25/$I$2>200,200,100+3.33*AQ25-AR25*AP25/$I$2),IF((AQ25*$I$2*100/(AR25*AP25))<100+AQ25-3.33*AR25*AP25/$I$2,100+AQ25-3.33*AR25*AP25/$I$2,IF((AQ25*$I$2*100/(AR25*AP25))>200,200,(AQ25*$I$2*100/(AR25*AP25))))),"") -> 95.602413 | AU25: =IF(AP25>0,MAX(K25:AO25),"") -> 28.8 | AV25: =IFERROR(VLOOKUP(A25,Maximos!A:AQ,8+(Precipitacion!$E$2-1)*3,FALSE),"") -> 59.6 | AW25: {=IFERROR( _xlfn.LET( _xlpm.mesNum, E$2, _xlpm.mesTxt, INDEX({"ENERO","FEBRERO","MARZO","ABRIL","MAYO","JUNIO","JULIO","AGOSTO","SEPTIEMBRE","OCTUBRE","NOVIEMBRE","DICIEMBRE"}, _xlpm.mesNum), _xlpm.colIni, MATCH(_xlpm.mesTxt, Maximos!$1:$1, 0), _xlpm.fila, MATCH($A25, Maximos!$A:$A, 0), _xlpm.anio, INDEX(Maximos!$A:$ZZ, _xlpm.fila, _xlpm.colIni+1), _xlpm.dia, INDEX(Maximos!$A:$ZZ, _xlpm.fila, _xlpm.colIni+2), IF(OR(_xlpm.anio="",_xlpm.dia=""), "No aplica", DATE(_xlpm.anio, _xlpm.mesNum, _xlpm.dia)) ), "")} -> 35242 | AX25: =IFERROR(AU25-AV25,"NA") -> -30.8
A26: 52055230 | B26: Aeropuerto San Luis - AUT | C26: Met_Aeronautica | D26: -77.67775 | E26: 0.85708333 | F26: 2961 | G26: 52 | H26: 52022 | I26: Nariño | J26: Aldana | K26: 0 | L26: 0.4 | M26: 0.4 | N26: 0.1 | O26: 0.1 | P26: 0 | Q26: 0 | R26: 7.7 | S26: 8.4 | T26: 0 | U26: 0 | V26: 1.3 | W26: 0.2 | X26: 2.6 | Y26: 1.2 | Z26: 0 | AA26: 0.7 | AB26: 0 | AC26: 0.6 | AD26: 0.9 | AE26: 0.9 | AF26: 1.1 | AG26: 0.5 | AH26: 0.2 | AI26: 0.5 | AJ26: 3.5 | AK26: 3.1 | AL26: 0.1 | AM26: 0.3 | AN26: 0 | AP26: =COUNTIF(K26:AO26,">=0") -> 30 | AQ26: =IF(AP26>0,SUM(K26:AO26),"") -> 34.8 | AR26: =IFERROR(VLOOKUP(A26,Climatologia_PP!A:U,9+Precipitacion!$E$2,FALSE),"") -> 52.293333 | AS26: =IFERROR((AQ26/AR26)*100,"") -> 66.54768 | AT26: =IFERROR(IF(AND((AQ26*$I$2*100/(AR26*AP26))>100+3.33*AQ26-AR26*AP26/$I$2,AR26<30),IF(100+3.33*AQ26-AR26*AP26/$I$2>200,200,100+3.33*AQ26-AR26*AP26/$I$2),IF((AQ26*$I$2*100/(AR26*AP26))<100+AQ26-3.33*AR26*AP26/$I$2,100+AQ26-3.33*AR26*AP26/$I$2,IF((AQ26*$I$2*100/(AR26*AP26))>200,200,(AQ26*$I$2*100/(AR26*AP26))))),"") -> 66.54768 | AU26: =IF(AP26>0,MAX(K26:AO26),"") -> 8.4 | AV26: =IFERROR(VLOOKUP(A26,Maximos!A:AQ,8+(Precipitacion!$E$2-1)*3,FALSE),"") -> 36 | AW26: {=IFERROR( _xlfn.LET( _xlpm.mesNum, E$2, _xlpm.mesTxt, INDEX({"ENERO","FEBRERO","MARZO","ABRIL","MAYO","JUNIO","JULIO","AGOSTO","SEPTIEMBRE","OCTUBRE","NOVIEMBRE","DICIEMBRE"}, _xlpm.mesNum), _xlpm.colIni, MATCH(_xlpm.mesTxt, Maximos!$1:$1, 0), _xlpm.fila, MATCH($A26, Maximos!$A:$A, 0), _xlpm.anio, INDEX(Maximos!$A:$ZZ, _xlpm.fila, _xlpm.colIni+1), _xlpm.dia, INDEX(Maximos!$A:$ZZ, _xlpm.fila, _xlpm.colIni+2), IF(OR(_xlpm.anio="",_xlpm.dia=""), "No aplica", DATE(_xlpm.anio, _xlpm.mesNum, _xlpm.dia)) ), "")} -> 25730 | AX26: =IFERROR(AU26-AV26,"NA") -> -27.6
A27: 11045010 | B27: Aeropuerto El Caraño | C27: Met_Aeronautica | D27: -76.643778 | E27: 5.6905556 | F27: 75 | G27: 27 | H27: 27001 | I27: Chocó | J27: Quibdó | K27: 15.6 | L27: 115.7 | M27: 0.9 | N27: 0.5 | O27: 23.6 | P27: 12.2 | Q27: 46.7 | R27: 4.3 | S27: 0 | T27: 0 | U27: 0 | V27: 0.8 | W27: 0.2 | X27: 26.8 | Y27: 47.6 | Z27: 45.1 | AA27: 30.3 | AB27: 0.3 | AC27: 0 | AD27: 28.6 | AE27: 20.8 | AF27: 56.9 | AG27: 0 | AH27: 0 | AI27: 19.3 | AJ27: 0 | AK27: 0 | AL27: 37.7 | AM27: 0.5 | AN27: 120.6 | AP27: =COUNTIF(K27:AO27,">=0") -> 30 | AQ27: =IF(AP27>0,SUM(K27:AO27),"") -> 655 | AR27: =IFERROR(VLOOKUP(A27,Climatologia_PP!A:U,9+Precipitacion!$E$2,FALSE),"") -> 774.80345 | AS27: =IFERROR((AQ27/AR27)*100,"") -> 84.537569 | AT27: =IFERROR(IF(AND((AQ27*$I$2*100/(AR27*AP27))>100+3.33*AQ27-AR27*AP27/$I$2,AR27<30),IF(100+3.33*AQ27-AR27*AP27/$I$2>200,200,100+3.33*AQ27-AR27*AP27/$I$2),IF((AQ27*$I$2*100/(AR27*AP27))<100+AQ27-3.33*AR27*AP27/$I$2,100+AQ27-3.33*AR27*AP27/$I$2,IF((AQ27*$I$2*100/(AR27*AP27))>200,200,(AQ27*$I$2*100/(AR27*AP27))))),"") -> 84.537569 | AU27: =IF(AP27>0,MAX(K27:AO27),"") -> 120.6 | AV27: =IFERROR(VLOOKUP(A27,Maximos!A:AQ,8+(Precipitacion!$E$2-1)*3,FALSE),"") -> 238 | AW27: {=IFERROR( _xlfn.LET( _xlpm.mesNum, E$2, _xlpm.mesTxt, INDEX({"ENERO","FEBRERO","MARZO","ABRIL","MAYO","JUNIO","JULIO","AGOSTO","SEPTIEMBRE","OCTUBRE","NOVIEMBRE","DICIEMBRE"}, _xlpm.mesNum), _xlpm.colIni, MATCH(_xlpm.mesTxt, Maximos!$1:$1, 0), _xlpm.fila, MATCH($A27, Maximos!$A:$A, 0), _xlpm.anio, INDEX(Maximos!$A:$ZZ, _xlpm.fila, _xlpm.colIni+1), _xlpm.dia, INDEX(Maximos!$A:$ZZ, _xlpm.fila, _xlpm.colIni+2), IF(OR(_xlpm.anio="",_xlpm.dia=""), "No aplica", DATE(_xlpm.anio, _xlpm.mesNum, _xlpm.dia)) ), "")} -> 27559 | AX27: =IFERROR(AU27-AV27,"NA") -> -117.4
A28: 37055010 | B28: Aeropuerto Santiago Pérez | C28: Met_Aeronautica | D28: -70.738056 | E28: 7.0694444 | F28: 128 | G28: 81 | H28: 81001 | I28: Arauca | J28: Arauca | K28: 27.3 | L28: 17.1 | M28: 10.6 | N28: 20.6 | O28: 0 | P28: 10.9 | Q28: 3.3 | R28: 7.1 | S28: 0 | T28: 0 | U28: 0 | V28: 0 | W28: 0 | X28: 3.2 | Y28: 18.1 | Z28: 2.2 | AA28: 5.4 | AB28: 1.8 | AC28: 0 | AD28: 0 | AE28: 18.7 | AF28: 14.3 | AG28: 0 | AH28: 16.6 | AI28: 0 | AJ28: 0 | AK28: 0 | AL28: 0.6 | AM28: 0 | AN28: 59.2 | AP28: =COUNTIF(K28:AO28,">=0") -> 30 | AQ28: =IF(AP28>0,SUM(K28:AO28),"") -> 237 | AR28: =IFERROR(VLOOKUP(A28,Climatologia_PP!A:U,9+Precipitacion!$E$2,FALSE),"") -> 308.0037 | AS28: =IFERROR((AQ28/AR28)*100,"") -> 76.947127 | AT28: =IFERROR(IF(AND((AQ28*$I$2*100/(AR28*AP28))>100+3.33*AQ28-AR28*AP28/$I$2,AR28<30),IF(100+3.33*AQ28-AR28*AP28/$I$2>200,200,100+3.33*AQ28-AR28*AP28/$I$2),IF((AQ28*$I$2*100/(AR28*AP28))<100+AQ28-3.33*AR28*AP28/$I$2,100+AQ28-3.33*AR28*AP28/$I$2,IF((AQ28*$I$2*100/(AR28*AP28))>200,200,(AQ28*$I$2*100/(AR28*AP28))))),"") -> 76.947127 | AU28: =IF(AP28>0,MAX(K28:AO28),"") -> 59.2 | AV28: =IFERROR(VLOOKUP(A28,Maximos!A:AQ,8+(Precipitacion!$E$2-1)*3,FALSE),"") -> 136.3 | AW28: {=IFERROR( _xlfn.LET( _xlpm.mesNum, E$2, _xlpm.mesTxt, INDEX({"ENERO","FEBRERO","MARZO","ABRIL","MAYO","JUNIO","JULIO","AGOSTO","SEPTIEMBRE","OCTUBRE","NOVIEMBRE","DICIEMBRE"}, _xlpm.mesNum), _xlpm.colIni, MATCH(_xlpm.mesTxt, Maximos!$1:$1, 0), _xlpm.fila, MATCH($A28, Maximos!$A:$A, 0), _xlpm.anio, INDEX(Maximos!$A:$ZZ, _xlpm.fila, _xlpm.colIni+1), _xlpm.dia, INDEX(Maximos!$A:$ZZ, _xlpm.fila, _xlpm.colIni+2), IF(OR(_xlpm.anio="",_xlpm.dia=""), "No aplica", DATE(_xlpm.anio, _xlpm.mesNum, _xlpm.dia)) ), "")} -> 38166 | AX28: =IFERROR(AU28-AV28,"NA") -> -77.1
A29: 38015030 | B29: Aeropuerto Puerto Carreño | C29: Met_Aeronautica | D29: -67.491222 | E29: 6.1824361 | F29: 57 | G29: 99 | H29: 99001 | I29: Vichada | J29: Puerto Carreño | K29: 1 | L29: 0.8 | M29: 24.1 | N29: 12.1 | O29: 29.3 | P29: 17.1 | Q29: 2.6 | R29: 7 | S29: 0 | T29: 102.8 | U29: 15.6 | V29: 0 | W29: 0 | X29: 51.7 | Y29: 109 | Z29: 8.6 | AA29: 11.7 | AB29: 3.2 | AC29: 0 | AD29: 1.4 | AE29: 25.5 | AF29: 10.9 | AG29: 1.4 | AH29: 47.7 | AI29: 0.5 | AJ29: 0 | AK29: 76.4 | AL29: 4.2 | AM29: 9.7 | AN29: 3.6 | AP29: =COUNTIF(K29:AO29,">=0") -> 30 | AQ29: =IF(AP29>0,SUM(K29:AO29),"") -> 577.9 | AR29: =IFERROR(VLOOKUP(A29,Climatologia_PP!A:U,9+Precipitacion!$E$2,FALSE),"") -> 475.93333 | AS29: =IFERROR((AQ29/AR29)*100,"") -> 121.42457 | AT29: =IFERROR(IF(AND((AQ29*$I$2*100/(AR29*AP29))>100+3.33*AQ29-AR29*AP29/$I$2,AR29<30),IF(100+3.33*AQ29-AR29*AP29/$I$2>200,200,100+3.33*AQ29-AR29*AP29/$I$2),IF((AQ29*$I$2*100/(AR29*AP29))<100+AQ29-3.33*AR29*AP29/$I$2,100+AQ29-3.33*AR29*AP29/$I$2,IF((AQ29*$I$2*100/(AR29*AP29))>200,200,(AQ29*$I$2*100/(AR29*AP29))))),"") -> 121.42457 | AU29: =IF(AP29>0,MAX(K29:AO29),"") -> 109 | AV29: =IFERROR(VLOOKUP(A29,Maximos!A:AQ,8+(Precipitacion!$E$2-1)*3,FALSE),"") -> 277 | AW29: {=IFERROR( _xlfn.LET( _xlpm.mesNum, E$2, _xlpm.mesTxt, INDEX({"ENERO","FEBRERO","MARZO","ABRIL","MAYO","JUNIO","JULIO","AGOSTO","SEPTIEMBRE","OCTUBRE","NOVIEMBRE","DICIEMBRE"}, _xlpm.mesNum), _xlpm.colIni, MATCH(_xlpm.mesTxt, Maximos!$1:$1, 0), _xlpm.fila, MATCH($A29, Maximos!$A:$A, 0), _xlpm.anio, INDEX(Maximos!$A:$ZZ, _xlpm.fila, _xlpm.colIni+1), _xlpm.dia, INDEX(Maximos!$A:$ZZ, _xlpm.fila, _xlpm.colIni+2), IF(OR(_xlpm.anio="",_xlpm.dia=""), "No aplica", DATE(_xlpm.anio, _xlpm.mesNum, _xlpm.dia)) ), "")} -> 39627 | AX29: =IFERROR(AU29-AV29,"NA") -> -168
A30: 35035020 | B30: Aeropuerto Vanguardia | C30: Met_Aeronautica | D30: -73.617578 | E30: 4.1619194 | F30: 422 | G30: 50 | H30: 50001 | I30: Meta | J30: Villavicencio | L30: 2.9 | M30: 2.3 | N30: 48.1 | O30: 18.4 | P30: 2.1 | Q30: 88.2 | R30: 16.1 | S30: 9.6 | T30: 0 | U30: 14.6 | V30: 0.1 | W30: 91.2 | X30: 35.2 | Y30: 3.1 | Z30: 0.5 | AA30: 3.7 | AB30: 1.5 | AC30: 2.9 | AD30: 19.1 | AE30: 10.7 | AF30: 2.8 | AG30: 5.2 | AH30: 0 | AI30: 0 | AJ30: 35.8 | AK30: 24.1 | AL30: 19.1 | AM30: 8.3 | AN30: 21.1 | AP30: =COUNTIF(K30:AO30,">=0") -> 29 | AQ30: =IF(AP30>0,SUM(K30:AO30),"") -> 486.7 | AR30: =IFERROR(VLOOKUP(A30,Climatologia_PP!A:U,9+Precipitacion!$E$2,FALSE),"") -> 545.93667 | AS30: =IFERROR((AQ30/AR30)*100,"") -> 89.149535 | AT30: =IFERROR(IF(AND((AQ30*$I$2*100/(AR30*AP30))>100+3.33*AQ30-AR30*AP30/$I$2,AR30<30),IF(100+3.33*AQ30-AR30*AP30/$I$2>200,200,100+3.33*AQ30-AR30*AP30/$I$2),IF((AQ30*$I$2*100/(AR30*AP30))<100+AQ30-3.33*AR30*AP30/$I$2,100+AQ30-3.33*AR30*AP30/$I$2,IF((AQ30*$I$2*100/(AR30*AP30))>200,200,(AQ30*$I$2*100/(AR30*AP30))))),"") -> 92.223657 | AU30: =IF(AP30>0,MAX(K30:AO30),"") -> 91.2 | AV30: =IFERROR(VLOOKUP(A30,Maximos!A:AQ,8+(Precipitacion!$E$2-1)*3,FALSE),"") -> 222.2 | AW30: {=IFERROR( _xlfn.LET( _xlpm.mesNum, E$2, _xlpm.mesTxt, INDEX({"ENERO","FEBRERO","MARZO","ABRIL","MAYO","JUNIO","JULIO","AGOSTO","SEPTIEMBRE","OCTUBRE","NOVIEMBRE","DICIEMBRE"}, _xlpm.mesNum), _xlpm.colIni, MATCH(_xlpm.mesTxt, Maximos!$1:$1, 0), _xlpm.fila, MATCH($A30, Maximos!$A:$A, 0), _xlpm.anio, INDEX(Maximos!$A:$ZZ, _xlpm.fila, _xlpm.colIni+1), _xlpm.dia, INDEX(Maximos!$A:$ZZ, _xlpm.fila, _xlpm.colIni+2), IF(OR(_xlpm.anio="",_xlpm.dia=""), "No aplica", DATE(_xlpm.anio, _xlpm.mesNum, _xlpm.dia)) ), "")} -> 11122 | AX30: =IFERROR(AU30-AV30,"NA") -> -131
A31: 48015050 | B31: Aeropuerto Vásquez Cobo | C31: Met_Aeronautica | D31: -69.940917 | E31: -4.1938611 | F31: 84 | G31: 91 | H31: 91001 | I31: Amazonas | J31: Leticia | K31: 24.2 | L31: 3.2 | M31: 0 | N31: 0 | O31: 6.6 | P31: 2.4 | Q31: 0.7 | R31: 20.7 | S31: 30.3 | T31: 30.4 | U31: 0 | V31: 0.2 | W31: 11.6 | X31: 0 | Y31: 4.5 | Z31: 10 | AA31: 16.6 | AB31: 0 | AC31: 11.8 | AD31: 2.6 | AE31: 5.9 | AF31: 0 | AG31: 0 | AH31: 26.8 | AI31: 0.4 | AJ31: 0 | AK31: 0 | AL31: 1.8 | AM31: 15.6 | AN31: 17.9 | AP31: =COUNTIF(K31:AO31,">=0") -> 30 | AQ31: =IF(AP31>0,SUM(K31:AO31),"") -> 244.2 | AR31: =IFERROR(VLOOKUP(A31,Climatologia_PP!A:U,9+Precipitacion!$E$2,FALSE),"") -> 211.48929 | AS31: =IFERROR((AQ31/AR31)*100,"") -> 115.46684 | AT31: =IFERROR(IF(AND((AQ31*$I$2*100/(AR31*AP31))>100+3.33*AQ31-AR31*AP31/$I$2,AR31<30),IF(100+3.33*AQ31-AR31*AP31/$I$2>200,200,100+3.33*AQ31-AR31*AP31/$I$2),IF((AQ31*$I$2*100/(AR31*AP31))<100+AQ31-3.33*AR31*AP31/$I$2,100+AQ31-3.33*AR31*AP31/$I$2,IF((AQ31*$I$2*100/(AR31*AP31))>200,200,(AQ31*$I$2*100/(AR31*AP31))))),"") -> 115.46684 | AU31: =IF(AP31>0,MAX(K31:AO31),"") -> 30.4 | AV31: =IFERROR(VLOOKUP(A31,Maximos!A:AQ,8+(Precipitacion!$E$2-1)*3,FALSE),"") -> 105 | AW31: {=IFERROR( _xlfn.LET( _xlpm.mesNum, E$2, _xlpm.mesTxt, INDEX({"ENERO","FEBRERO","MARZO","ABRIL","MAYO","JUNIO","JULIO","AGOSTO","SEPTIEMBRE","OCTUBRE","NOVIEMBRE","DICIEMBRE"}, _xlpm.mesNum), _xlpm.colIni, MATCH(_xlpm.mesTxt, Maximos!$1:$1, 0), _xlpm.fila, MATCH($A31, Maximos!$A:$A, 0), _xlpm.anio, INDEX(Maximos!$A:$ZZ, _xlpm.fila, _xlpm.colIni+1), _xlpm.dia, INDEX(Maximos!$A:$ZZ, _xlpm.fila, _xlpm.colIni+2), IF(OR(_xlpm.anio="",_xlpm.dia=""), "No aplica", DATE(_xlpm.anio, _xlpm.mesNum, _xlpm.dia)) ), "")} -> 34494 | AX31: =IFERROR(AU31-AV31,"NA") -> -74.6
A32: 26190090 | B32: Betania-Las Guacas | C32: Area Operativa 01 - Antioquia-Chocó | D32: -75.975528 | E32: 5.755 | F32: 1600 | G32: 5 | H32: 5091 | I32: Antioquia | J32: Betania | K32: 0 | L32: 14 | M32: 2 | N32: 72 | O32: 16 | P32: 8 | Q32: 23 | R32: 44 | S32: 3 | T32: 0 | U32: 0 | V32: 0 | W32: 0 | X32: 13 | Y32: 0 | Z32: 0 | AA32: 9 | AB32: 2 | AC32: 5 | AD32: 7 | AE32: 0 | AF32: 21 | AG32: 0 | AH32: 0 | AI32: 0 | AJ32: 0 | AK32: 0 | AL32: 0 | AM32: 0 | AN32: 0 | AP32: =COUNTIF(K32:AO32,">=0") -> 30 | AQ32: =IF(AP32>0,SUM(K32:AO32),"") -> 239 | AR32: =IFERROR(VLOOKUP(A32,Climatologia_PP!A:U,9+Precipitacion!$E$2,FALSE),"") -> 225.48276 | AS32: =IFERROR((AQ32/AR32)*100,"") -> 105.9948 | AT32: =IFERROR(IF(AND((AQ32*$I$2*100/(AR32*AP32))>100+3.33*AQ32-AR32*AP32/$I$2,AR32<30),IF(100+3.33*AQ32-AR32*AP32/$I$2>200,200,100+3.33*AQ32-AR32*AP32/$I$2),IF((AQ32*$I$2*100/(AR32*AP32))<100+AQ32-3.33*AR32*AP32/$I$2,100+AQ32-3.33*AR32*AP32/$I$2,IF((AQ32*$I$2*100/(AR32*AP32))>200,200,(AQ32*$I$2*100/(AR32*AP32))))),"") -> 105.9948 | AU32: =IF(AP32>0,MAX(K32:AO32),"") -> 72 | AV32: =IFERROR(VLOOKUP(A32,Maximos!A:AQ,8+(Precipitacion!$E$2-1)*3,FALSE),"") -> 91 | AW32: {=IFERROR( _xlfn.LET( _xlpm.mesNum, E$2, _xlpm.mesTxt, INDEX({"ENERO","FEBRERO","MARZO","ABRIL","MAYO","JUNIO","JULIO","AGOSTO","SEPTIEMBRE","OCTUBRE","NOVIEMBRE","DICIEMBRE"}, _xlpm.mesNum), _xlpm.colIni, MATCH(_xlpm.mesTxt, Maximos!$1:$1, 0), _xlpm.fila, MATCH($A32, Maximos!$A:$A, 0), _xlpm.anio, INDEX(Maximos!$A:$ZZ, _xlpm.fila, _xlpm.colIni+1), _xlpm.dia, INDEX(Maximos!$A:$ZZ, _xlpm.fila, _xlpm.colIni+2), IF(OR(_xlpm.anio="",_xlpm.dia=""), "No aplica", DATE(_xlpm.anio, _xlpm.mesNum, _xlpm.dia)) ), "")} -> 30862 | AX32: =IFERROR(AU32-AV32,"NA") -> -19
A33: 12015020 | B33: Uniban | C33: Area Operativa 01 - Antioquia-Chocó | D33: -76.651333 | E33: 7.8259167 | F33: 43 | G33: 5 | H33: 5045 | I33: Antioquia | J33: Apartadó | K33: 0.6 | L33: 20.3 | M33: 0.8 | N33: 2 | O33: 0.7 | P33: 0.8 | Q33: 0.4 | R33: 0.5 | S33: 0 | T33: 0 | U33: 0 | V33: 0.6 | W33: 0.5 | X33: 5 | Y33: 4.6 | Z33: 61 | AA33: 2.7 | AB33: 0.2 | AC33: 4.5 | AD33: 3.8 | AE33: 0.7 | AF33: 74 | AG33: 0 | AH33: 6.1 | AI33: 4.2 | AJ33: 0.4 | AK33: 0 | AL33: 13 | AM33: 0 | AN33: 1.5 | AP33: =COUNTIF(K33:AO33,">=0") -> 30 | AQ33: =IF(AP33>0,SUM(K33:AO33),"") -> 208.9 | AR33: =IFERROR(VLOOKUP(A33,Climatologia_PP!A:U,9+Precipitacion!$E$2,FALSE),"") -> 265.92692 | AS33: =IFERROR((AQ33/AR33)*100,"") -> 78.555416 | AT33: =IFERROR(IF(AND((AQ33*$I$2*100/(AR33*AP33))>100+3.33*AQ33-AR33*AP33/$I$2,AR33<30),IF(100+3.33*AQ33-AR33*AP33/$I$2>200,200,100+3.33*AQ33-AR33*AP33/$I$2),IF((AQ33*$I$2*100/(AR33*AP33))<100+AQ33-3.33*AR33*AP33/$I$2,100+AQ33-3.33*AR33*AP33/$I$2,IF((AQ33*$I$2*100/(AR33*AP33))>200,200,(AQ33*$I$2*100/(AR33*AP33))))),"") -> 78.555416 | AU33: =IF(AP33>0,MAX(K33:AO33),"") -> 74 | AV33: =IFERROR(VLOOKUP(A33,Maximos!A:AQ,8+(Precipitacion!$E$2-1)*3,FALSE),"") -> 132 | AW33: {=IFERROR( _xlfn.LET( _xlpm.mesNum, E$2, _xlpm.mesTxt, INDEX({"ENERO","FEBRERO","MARZO","ABRIL","MAYO","JUNIO","JULIO","AGOSTO","SEPTIEMBRE","OCTUBRE","NOVIEMBRE","DICIEMBRE"}, _xlpm.mesNum), _xlpm.colIni, MATCH(_xlpm.mesTxt, Maximos!$1:$1, 0), _xlpm.fila, MATCH($A33, Maximos!$A:$A, 0), _xlpm.anio, INDEX(Maximos!$A:$ZZ, _xlpm.fila, _xlpm.colIni+1), _xlpm.dia, INDEX(Maximos!$A:$ZZ, _xlpm.fila, _xlpm.colIni+2), IF(OR(_xlpm.anio="",_xlpm.dia=""), "No aplica", DATE(_xlpm.anio, _xlpm.mesNum, _xlpm.dia)) ), "")} -> 32304 | AX33: =IFERROR(AU33-AV33,"NA") -> -58
A34: 26240100 | B34: Guarumo-La Lucha | C34: Area Operativa 01 - Antioquia-Chocó | D34: -75.214917 | E34: 7.8629167 | F34: 70 | G34: 5 | H34: 5120 | I34: Antioquia | J34: Cáceres | K34: 0 | L34: 24 | M34: 0 | N34: 17 | O34: 4 | P34: 47 | Q34: 0 | R34: 1 | S34: 0 | T34: 11 | U34: 0 | V34: 0 | W34: 0 | X34: 22 | Y34: 0 | Z34: 7 | AA34: 28 | AB34: 2 | AC34: 0 | AD34: 0 | AE34: 0 | AF34: 0 | AG34: 0 | AH34: 0 | AI34: 24 | AJ34: 0 | AK34: 0 | AL34: 0 | AM34: 0 | AN34: 35 | AP34: =COUNTIF(K34:AO34,">=0") -> 30 | AQ34: =IF(AP34>0,SUM(K34:AO34),"") -> 222 | AR34: =IFERROR(VLOOKUP(A34,Climatologia_PP!A:U,9+Precipitacion!$E$2,FALSE),"") -> 345.68667 | AS34: =IFERROR((AQ34/AR34)*100,"") -> 64.220007 | AT34: =IFERROR(IF(AND((AQ34*$I$2*100/(AR34*AP34))>100+3.33*AQ34-AR34*AP34/$I$2,AR34<30),IF(100+3.33*AQ34-AR34*AP34/$I$2>200,200,100+3.33*AQ34-AR34*AP34/$I$2),IF((AQ34*$I$2*100/(AR34*AP34))<100+AQ34-3.33*AR34*AP34/$I$2,100+AQ34-3.33*AR34*AP34/$I$2,IF((AQ34*$I$2*100/(AR34*AP34))>200,200,(AQ34*$I$2*100/(AR34*AP34))))),"") -> 64.220007 | AU34: =IF(AP34>0,MAX(K34:AO34),"") -> 47 | AV34: =IFERROR(VLOOKUP(A34,Maximos!A:AQ,8+(Precipitacion!$E$2-1)*3,FALSE),"") -> 147 | AW34: {=IFERROR( _xlfn.LET( _xlpm.mesNum, E$2, _xlpm.mesTxt, INDEX({"ENERO","FEBRERO","MARZO","ABRIL","MAYO","JUNIO","JULIO","AGOSTO","SEPTIEMBRE","OCTUBRE","NOVIEMBRE","DICIEMBRE"}, _xlpm.mesNum), _xlpm.colIni, MATCH(_xlpm.mesTxt, Maximos!$1:$1, 0), _xlpm.fila, MATCH($A34, Maximos!$A:$A, 0), _xlpm.anio, INDEX(Maximos!$A:$ZZ, _xlpm.fila, _xlpm.colIni+1), _xlpm.dia, INDEX(Maximos!$A:$ZZ, _xlpm.fila, _xlpm.colIni+2), IF(OR(_xlpm.anio="",_xlpm.dia=""), "No aplica", DATE(_xlpm.anio, _xlpm.mesNum, _xlpm.dia)) ), "")} -> 42902 | AX34: =IFERROR(AU34-AV34,"NA") -> -100
A35: 26240160 | B35: La Coquera | C35: Area Operativa 01 - Antioquia-Chocó | D35: -75.2 | E35: 7.96 | F35: 49 | G35: 5 | H35: 5154 | I35: Antioquia | J35: Caucasia | K35: 0 | L35: 16 | M35: 0 | N35: 15 | O35: 2 | P35: 10 | Q35: 0 | R35: 0 | S35: 0 | T35: 0 | U35: 0 | V35: 0 | W35: 0 | X35: 19 | Y35: 0 | Z35: 12 | AA35: 70 | AB35: 0 | AC35: 0 | AD35: 0 | AE35: 0 | AF35: 0 | AG35: 0 | AH35: 0 | AI35: 26 | AJ35: 0 | AK35: 0 | AL35: 0 | AM35: 0 | AN35: 8 | AP35: =COUNTIF(K35:AO35,">=0") -> 30 | AQ35: =IF(AP35>0,SUM(K35:AO35),"") -> 178 | AR35: =IFERROR(VLOOKUP(A35,Climatologia_PP!A:U,9+Precipitacion!$E$2,FALSE),"") -> 355.57857 | AS35: =IFERROR((AQ35/AR35)*100,"") -> 50.05926 | AT35: =IFERROR(IF(AND((AQ35*$I$2*100/(AR35*AP35))>100+3.33*AQ35-AR35*AP35/$I$2,AR35<30),IF(100+3.33*AQ35-AR35*AP35/$I$2>200,200,100+3.33*AQ35-AR35*AP35/$I$2),IF((AQ35*$I$2*100/(AR35*AP35))<100+AQ35-3.33*AR35*AP35/$I$2,100+AQ35-3.33*AR35*AP35/$I$2,IF((AQ35*$I$2*100/(AR35*AP35))>200,200,(AQ35*$I$2*100/(AR35*AP35))))),"") -> 50.05926 | AU35: =IF(AP35>0,MAX(K35:AO35),"") -> 70 | AV35: =IFERROR(VLOOKUP(A35,Maximos!A:AQ,8+(Precipitacion!$E$2-1)*3,FALSE),"") -> 155 | AW35: {=IFERROR( _xlfn.LET( _xlpm.mesNum, E$2, _xlpm.mesTxt, INDEX({"ENERO","FEBRERO","MARZO","ABRIL","MAYO","JUNIO","JULIO","AGOSTO","SEPTIEMBRE","OCTUBRE","NOVIEMBRE","DICIEMBRE"}, _xlpm.mesNum), _xlpm.colIni, MATCH(_xlpm.mesTxt, Maximos!$1:$1, 0), _xlpm.fila, MATCH($A35, Maximos!$A:$A, 0), _xlpm.anio, INDEX(Maximos!$A:$ZZ, _xlpm.fila, _xlpm.colIni+1), _xlpm.dia, INDEX(Maximos!$A:$ZZ, _xlpm.fila, _xlpm.colIni+2), IF(OR(_xlpm.anio="",_xlpm.dia=""), "No aplica", DATE(_xlpm.anio, _xlpm.mesNum, _xlpm.dia)) ), "")} -> 35594 | AX35: =IFERROR(AU35-AV35,"NA") -> -85
A36: 27015260 | B36: La Salada | C36: Area Operativa 01 - Antioquia-Chocó | D36: -75.624667 | E36: 6.0483611 | F36: 1923 | G36: 5 | H36: 5129 | I36: Antioquia | J36: Caldas | K36: 20.7 | L36: 0.2 | M36: 6.8 | N36: 7.8 | O36: 2.4 | P36: 8.1 | Q36: 27 | R36: 10.2 | S36: 0.7 | T36: 10.5 | U36: 0.2 | V36: 0 | W36: 0 | X36: 2.1 | Y36: 8.4 | Z36: 0.5 | AA36: 8.8 | AB36: 9.9 | AC36: 7.3 | AD36: 9.9 | AE36: 0.9 | AF36: 9.4 | AG36: 0 | AH36: 0 | AI36: 0 | AJ36: 0 | AK36: 0 | AL36: 0 | AM36: 0 | AN36: 0 | AP36: =COUNTIF(K36:AO36,">=0") -> 30 | AQ36: =IF(AP36>0,SUM(K36:AO36),"") -> 151.8 | AR36: =IFERROR(VLOOKUP(A36,Climatologia_PP!A:U,9+Precipitacion!$E$2,FALSE),"") -> 210.825 | AS36: =IFERROR((AQ36/AR36)*100,"") -> 72.002846 | AT36: =IFERROR(IF(AND((AQ36*$I$2*100/(AR36*AP36))>100+3.33*AQ36-AR36*AP36/$I$2,AR36<30),IF(100+3.33*AQ36-AR36*AP36/$I$2>200,200,100+3.33*AQ36-AR36*AP36/$I$2),IF((AQ36*$I$2*100/(AR36*AP36))<100+AQ36-3.33*AR36*AP36/$I$2,100+AQ36-3.33*AR36*AP36/$I$2,IF((AQ36*$I$2*100/(AR36*AP36))>200,200,(AQ36*$I$2*100/(AR36*AP36))))),"") -> 72.002846 | AU36: =IF(AP36>0,MAX(K36:AO36),"") -> 27 | AV36: =IFERROR(VLOOKUP(A36,Maximos!A:AQ,8+(Precipitacion!$E$2-1)*3,FALSE),"") -> 95.1 | AW36: {=IFERROR( _xlfn.LET( _xlpm.mesNum, E$2, _xlpm.mesTxt, INDEX({"ENERO","FEBRERO","MARZO","ABRIL","MAYO","JUNIO","JULIO","AGOSTO","SEPTIEMBRE","OCTUBRE","NOVIEMBRE","DICIEMBRE"}, _xlpm.mesNum), _xlpm.colIni, MATCH(_xlpm.mesTxt, Maximos!$1:$1, 0), _xlpm.fila, MATCH($A36, Maximos!$A:$A, 0), _xlpm.anio, INDEX(Maximos!$A:$ZZ, _xlpm.fila, _xlpm.colIni+1), _xlpm.dia, INDEX(Maximos!$A:$ZZ, _xlpm.fila, _xlpm.colIni+2), IF(OR(_xlpm.anio="",_xlpm.dia=""), "No aplica", DATE(_xlpm.anio, _xlpm.mesNum, _xlpm.dia)) ), "")} -> 36322 | AX36: =IFERROR(AU36-AV36,"NA") -> -68.1
A37: 23080650 | B37: Campoalegre | C37: Area Operativa 01 - Antioquia-Chocó | D37: -75.335611 | E37: 6.0737778 | F37: 2183 | G37: 5 | H37: 5148 | I37: Antioquia | J37: El Carmen De Viboral | K37: 0 | L37: 0 | M37: 5 | N37: 1 | O37: 0 | P37: 4 | Q37: 30 | R37: 16 | S37: 3 | T37: 8 | U37: 0 | V37: 0 | W37: 4 | X37: 3 | Y37: 0 | Z37: 0 | AA37: 23 | AB37: 25 | AC37: 19 | AD37: 20 | AE37: 36 | AF37: 54 | AG37: 0 | AH37: 0 | AI37: 0 | AJ37: 0 | AK37: 0 | AL37: 0 | AM37: 0 | AN37: 0 | AP37: =COUNTIF(K37:AO37,">=0") -> 30 | AQ37: =IF(AP37>0,SUM(K37:AO37),"") -> 251 | AR37: =IFERROR(VLOOKUP(A37,Climatologia_PP!A:U,9+Precipitacion!$E$2,FALSE),"") -> 283.03333 | AS37: =IFERROR((AQ37/AR37)*100,"") -> 88.682134 | AT37: =IFERROR(IF(AND((AQ37*$I$2*100/(AR37*AP37))>100+3.33*AQ37-AR37*AP37/$I$2,AR37<30),IF(100+3.33*AQ37-AR37*AP37/$I$2>200,200,100+3.33*AQ37-AR37*AP37/$I$2),IF((AQ37*$I$2*100/(AR37*AP37))<100+AQ37-3.33*AR37*AP37/$I$2,100+AQ37-3.33*AR37*AP37/$I$2,IF((AQ37*$I$2*100/(AR37*AP37))>200,200,(AQ37*$I$2*100/(AR37*AP37))))),"") -> 88.682134 | AU37: =IF(AP37>0,MAX(K37:AO37),"") -> 54 | AV37: =IFERROR(VLOOKUP(A37,Maximos!A:AQ,8+(Precipitacion!$E$2-1)*3,FALSE),"") -> 93 | AW37: {=IFERROR( _xlfn.LET( _xlpm.mesNum, E$2, _xlpm.mesTxt, INDEX({"ENERO","FEBRERO","MARZO","ABRIL","MAYO","JUNIO","JULIO","AGOSTO","SEPTIEMBRE","OCTUBRE","NOVIEMBRE","DICIEMBRE"}, _xlpm.mesNum), _xlpm.colIni, MATCH(_xlpm.mesTxt, Maximos!$1:$1, 0), _xlpm.fila, MATCH($A37, Maximos!$A:$A, 0), _xlpm.anio, INDEX(Maximos!$A:$ZZ, _xlpm.fila, _xlpm.colIni+1), _xlpm.dia, INDEX(Maximos!$A:$ZZ, _xlpm.fila, _xlpm.colIni+2), IF(OR(_xlpm.anio="",_xlpm.dia=""), "No aplica", DATE(_xlpm.anio, _xlpm.mesNum, _xlpm.dia)) ), "")} -> 36312 | AX37: =IFERROR(AU37-AV37,"NA") -> -39
A38: 26210080 | B38: La Herradura | C38: Area Operativa 01 - Antioquia-Chocó | D38: -75.873972 | E38: 6.0992222 | F38: 849 | G38: 5 | H38: 5209 | I38: Antioquia | J38: Concordia | K38: 0 | L38: 2 | M38: 51 | N38: 12 | O38: 18 | P38: 27 | Q38: 34 | R38: 9 | S38: 3 | T38: 0 | U38: 0 | V38: 0 | W38: 0 | X38: 0 | Y38: 0 | Z38: 6 | AA38: 13 | AB38: 6 | AC38: 7 | AD38: 10 | AE38: 0 | AF38: 18 | AG38: 0 | AH38: 0 | AI38: 0 | AJ38: 0 | AK38: 0 | AL38: 3 | AM38: 0 | AN38: 0 | AP38: =COUNTIF(K38:AO38,">=0") -> 30 | AQ38: =IF(AP38>0,SUM(K38:AO38),"") -> 219 | AR38: =IFERROR(VLOOKUP(A38,Climatologia_PP!A:U,9+Precipitacion!$E$2,FALSE),"") -> 199 | AS38: =IFERROR((AQ38/AR38)*100,"") -> 110.05025 | AT38: =IFERROR(IF(AND((AQ38*$I$2*100/(AR38*AP38))>100+3.33*AQ38-AR38*AP38/$I$2,AR38<30),IF(100+3.33*AQ38-AR38*AP38/$I$2>200,200,100+3.33*AQ38-AR38*AP38/$I$2),IF((AQ38*$I$2*100/(AR38*AP38))<100+AQ38-3.33*AR38*AP38/$I$2,100+AQ38-3.33*AR38*AP38/$I$2,IF((AQ38*$I$2*100/(AR38*AP38))>200,200,(AQ38*$I$2*100/(AR38*AP38))))),"") -> 110.05025 | AU38: =IF(AP38>0,MAX(K38:AO38),"") -> 51 | AV38: =IFERROR(VLOOKUP(A38,Maximos!A:AQ,8+(Precipitacion!$E$2-1)*3,FALSE),"") -> 201 | AW38: {=IFERROR( _xlfn.LET( _xlpm.mesNum, E$2, _xlpm.mesTxt, INDEX({"ENERO","FEBRERO","MARZO","ABRIL","MAYO","JUNIO","JULIO","AGOSTO","SEPTIEMBRE","OCTUBRE","NOVIEMBRE","DICIEMBRE"}, _xlpm.mesNum), _xlpm.colIni, MATCH(_xlpm.mesTxt, Maximos!$1:$1, 0), _xlpm.fila, MATCH($A38, Maximos!$A:$A, 0), _xlpm.anio, INDEX(Maximos!$A:$ZZ, _xlpm.fila, _xlpm.colIni+1), _xlpm.dia, INDEX(Maximos!$A:$ZZ, _xlpm.fila, _xlpm.colIni+2), IF(OR(_xlpm.anio="",_xlpm.dia=""), "No aplica", DATE(_xlpm.anio, _xlpm.mesNum, _xlpm.dia)) ), "")} -> 30114 | AX38: =IFERROR(AU38-AV38,"NA") -> -150
